2025-03-01 20:02:07,846 - INFO - image_utils.py:94 - Generated placeholder image at placeholder.png
2025-03-01 20:02:07,847 - INFO - app.py:69 - Available images in C:\Users\alexa\dev\AiR-Helix-View\frontend\public\images:
2025-03-01 20:02:07,851 - INFO - app.py:74 -  - allianz_stadium_sydney01.jpg
2025-03-01 20:02:07,852 - INFO - app.py:74 -  - allianz_stadium_sydney03.jpg
2025-03-01 20:02:07,852 - INFO - app.py:74 -  - allianz_stadium_sydney05.jpg
2025-03-01 20:02:07,852 - INFO - app.py:74 -  - allianz_stadium_sydney10.jpg
2025-03-01 20:02:07,858 - INFO - app.py:74 -  - campbelltown_stadium04.jpg
2025-03-01 20:02:07,890 - INFO - app.py:74 -  - canberra_stadium01.jpg
2025-03-01 20:02:07,891 - INFO - app.py:74 -  - canberra_stadium02.jpg
2025-03-01 20:02:07,892 - INFO - app.py:74 -  - canberra_stadium03.jpg
2025-03-01 20:02:07,892 - INFO - app.py:74 -  - canberra_stadium04.jpg
2025-03-01 20:02:07,893 - INFO - app.py:74 -  - central_coast_stadium01.jpg
2025-03-01 20:02:07,899 - INFO - app.py:77 -  ... and 113 more images
2025-03-01 20:02:07,899 - INFO - app.py:78 - Total images found: 123
2025-03-01 20:02:15,682 - DEBUG - _pool.py:633 - [#0000]  _: <POOL> created, direct address IPv4Address(('localhost', 7687))
2025-03-01 20:02:15,683 - DEBUG - workspace.py:230 - [#0000]  _: <WORKSPACE> routing towards fixed database: None
2025-03-01 20:02:15,684 - DEBUG - workspace.py:122 - [#0000]  _: <WORKSPACE> pinning database: None
2025-03-01 20:02:15,684 - DEBUG - _pool.py:655 - [#0000]  _: <POOL> acquire direct connection, access_mode='READ', database=AcquisitionDatabase(name=None, guessed=False)
2025-03-01 20:02:15,685 - DEBUG - _pool.py:407 - [#0000]  _: <POOL> trying to hand out new connection
2025-03-01 20:02:15,685 - DEBUG - _util.py:178 - [#0000]  _: <RESOLVE> in: localhost:7687
2025-03-01 20:02:15,690 - DEBUG - _util.py:199 - [#0000]  _: <RESOLVE> dns resolver out: [::1]:7687
2025-03-01 20:02:15,692 - DEBUG - _bolt_socket.py:408 - [#0000]  C: <OPEN> [::1]:7687
2025-03-01 20:02:17,748 - DEBUG - _bolt_socket.py:420 - [#0000]  S: <ERROR> ConnectionRefusedError 10061 'No connection could be made because the target machine actively refused it' None 10061 None
2025-03-01 20:02:17,749 - DEBUG - _bolt_socket.py:457 - [#0000]  C: <CLOSE> [::1]:7687
2025-03-01 20:02:17,750 - DEBUG - _bolt_socket.py:343 - [#0000]  S: <CONNECTION FAILED> [::1]:7687 ServiceUnavailable: Failed to establish connection to ResolvedIPv6Address(('::1', 7687, 0, 0)) (reason [WinError 10061] No connection could be made because the target machine actively refused it)
2025-03-01 20:02:17,752 - DEBUG - _util.py:199 - [#0000]  _: <RESOLVE> dns resolver out: 127.0.0.1:7687
2025-03-01 20:02:17,753 - DEBUG - _bolt_socket.py:408 - [#0000]  C: <OPEN> 127.0.0.1:7687
2025-03-01 20:02:17,764 - DEBUG - _bolt_socket.py:239 - [#FE22]  C: <MAGIC> 0x6060B017
2025-03-01 20:02:17,764 - DEBUG - _bolt_socket.py:244 - [#FE22]  C: <HANDSHAKE> 0x000001FF 0x00080805 0x00020404 0x00000003
2025-03-01 20:02:17,769 - DEBUG - _bolt_socket.py:80 - [#FE22]  S: <HANDSHAKE> 0x00000605
2025-03-01 20:02:17,770 - DEBUG - _bolt5.py:728 - [#FE22]  C: HELLO {'user_agent': 'neo4j-python/5.28.1 Python/3.10.11-final-0 (win32)', 'bolt_agent': {'product': 'neo4j-python/5.28.1', 'platform': 'Windows 10; AMD64', 'language': 'Python/3.10.11-final-0', 'language_details': 'CPython; 3.10.11-final-0 (tags/v3.10.11:7d4cc5a, Apr  5 2023 00:38:17) [MSC v.1929 64 bit (AMD64)]'}}
2025-03-01 20:02:17,772 - DEBUG - _bolt5.py:100 - [#FE22]  _: <CONNECTION> client state: CONNECTED > AUTHENTICATION
2025-03-01 20:02:17,774 - DEBUG - _bolt5.py:666 - [#FE22]  C: LOGON {'scheme': 'basic', 'principal': 'neo4j', 'credentials': '*******'}
2025-03-01 20:02:17,775 - DEBUG - _bolt5.py:100 - [#FE22]  _: <CONNECTION> client state: AUTHENTICATION > READY
2025-03-01 20:02:17,785 - DEBUG - _bolt5.py:484 - [#FE22]  S: SUCCESS {'server': 'Neo4j/5.24.0', 'connection_id': 'bolt-3', 'hints': {'connection.recv_timeout_seconds': 120}}
2025-03-01 20:02:17,785 - DEBUG - _bolt5.py:89 - [#FE22]  _: <CONNECTION> server state: CONNECTED > AUTHENTICATION
2025-03-01 20:02:17,791 - DEBUG - _bolt5.py:484 - [#FE22]  S: SUCCESS {}
2025-03-01 20:02:17,792 - DEBUG - _bolt5.py:89 - [#FE22]  _: <CONNECTION> server state: AUTHENTICATION > READY
2025-03-01 20:02:17,793 - DEBUG - _pool.py:501 - [#FE22]  _: <POOL> released bolt-3
2025-03-01 20:02:17,793 - INFO - database.py:16 - Connected to Neo4j database
2025-03-01 20:02:17,794 - INFO - app.py:86 - Database connection verified
2025-03-01 20:02:17,832 - INFO - template_utils.py:23 - Created template file: templates\admin.html
2025-03-01 20:02:17,835 - INFO - template_utils.py:23 - Created template file: templates\logs.html
2025-03-01 20:02:17,852 - INFO - app.py:93 - Starting Flask application...
2025-03-01 20:02:17,892 - INFO - _internal.py:97 - [31m[1mWARNING: This is a development server. Do not use it in a production deployment. Use a production WSGI server instead.[0m
 * Running on http://127.0.0.1:5001
2025-03-01 20:02:17,893 - INFO - _internal.py:97 - [33mPress CTRL+C to quit[0m
2025-03-01 20:02:17,898 - INFO - _internal.py:97 -  * Restarting with stat
2025-03-01 20:02:18,548 - INFO - image_utils.py:94 - Generated placeholder image at placeholder.png
2025-03-01 20:02:18,549 - INFO - app.py:69 - Available images in C:\Users\alexa\dev\AiR-Helix-View\frontend\public\images:
2025-03-01 20:02:18,552 - INFO - app.py:74 -  - allianz_stadium_sydney01.jpg
2025-03-01 20:02:18,553 - INFO - app.py:74 -  - allianz_stadium_sydney03.jpg
2025-03-01 20:02:18,553 - INFO - app.py:74 -  - allianz_stadium_sydney05.jpg
2025-03-01 20:02:18,554 - INFO - app.py:74 -  - allianz_stadium_sydney10.jpg
2025-03-01 20:02:18,554 - INFO - app.py:74 -  - campbelltown_stadium04.jpg
2025-03-01 20:02:18,555 - INFO - app.py:74 -  - canberra_stadium01.jpg
2025-03-01 20:02:18,555 - INFO - app.py:74 -  - canberra_stadium02.jpg
2025-03-01 20:02:18,556 - INFO - app.py:74 -  - canberra_stadium03.jpg
2025-03-01 20:02:18,556 - INFO - app.py:74 -  - canberra_stadium04.jpg
2025-03-01 20:02:18,557 - INFO - app.py:74 -  - central_coast_stadium01.jpg
2025-03-01 20:02:18,562 - INFO - app.py:77 -  ... and 113 more images
2025-03-01 20:02:18,563 - INFO - app.py:78 - Total images found: 123
2025-03-01 20:02:26,282 - DEBUG - _pool.py:633 - [#0000]  _: <POOL> created, direct address IPv4Address(('localhost', 7687))
2025-03-01 20:02:26,283 - DEBUG - workspace.py:230 - [#0000]  _: <WORKSPACE> routing towards fixed database: None
2025-03-01 20:02:26,284 - DEBUG - workspace.py:122 - [#0000]  _: <WORKSPACE> pinning database: None
2025-03-01 20:02:26,284 - DEBUG - _pool.py:655 - [#0000]  _: <POOL> acquire direct connection, access_mode='READ', database=AcquisitionDatabase(name=None, guessed=False)
2025-03-01 20:02:26,284 - DEBUG - _pool.py:407 - [#0000]  _: <POOL> trying to hand out new connection
2025-03-01 20:02:26,284 - DEBUG - _util.py:178 - [#0000]  _: <RESOLVE> in: localhost:7687
2025-03-01 20:02:26,289 - DEBUG - _util.py:199 - [#0000]  _: <RESOLVE> dns resolver out: [::1]:7687
2025-03-01 20:02:26,290 - DEBUG - _bolt_socket.py:408 - [#0000]  C: <OPEN> [::1]:7687
2025-03-01 20:02:28,349 - DEBUG - _bolt_socket.py:420 - [#0000]  S: <ERROR> ConnectionRefusedError 10061 'No connection could be made because the target machine actively refused it' None 10061 None
2025-03-01 20:02:28,350 - DEBUG - _bolt_socket.py:457 - [#0000]  C: <CLOSE> [::1]:7687
2025-03-01 20:02:28,350 - DEBUG - _bolt_socket.py:343 - [#0000]  S: <CONNECTION FAILED> [::1]:7687 ServiceUnavailable: Failed to establish connection to ResolvedIPv6Address(('::1', 7687, 0, 0)) (reason [WinError 10061] No connection could be made because the target machine actively refused it)
2025-03-01 20:02:28,351 - DEBUG - _util.py:199 - [#0000]  _: <RESOLVE> dns resolver out: 127.0.0.1:7687
2025-03-01 20:02:28,352 - DEBUG - _bolt_socket.py:408 - [#0000]  C: <OPEN> 127.0.0.1:7687
2025-03-01 20:02:28,353 - DEBUG - _bolt_socket.py:239 - [#FE31]  C: <MAGIC> 0x6060B017
2025-03-01 20:02:28,354 - DEBUG - _bolt_socket.py:244 - [#FE31]  C: <HANDSHAKE> 0x000001FF 0x00080805 0x00020404 0x00000003
2025-03-01 20:02:28,360 - DEBUG - _bolt_socket.py:80 - [#FE31]  S: <HANDSHAKE> 0x00000605
2025-03-01 20:02:28,362 - DEBUG - _bolt5.py:728 - [#FE31]  C: HELLO {'user_agent': 'neo4j-python/5.28.1 Python/3.10.11-final-0 (win32)', 'bolt_agent': {'product': 'neo4j-python/5.28.1', 'platform': 'Windows 10; AMD64', 'language': 'Python/3.10.11-final-0', 'language_details': 'CPython; 3.10.11-final-0 (tags/v3.10.11:7d4cc5a, Apr  5 2023 00:38:17) [MSC v.1929 64 bit (AMD64)]'}}
2025-03-01 20:02:28,363 - DEBUG - _bolt5.py:100 - [#FE31]  _: <CONNECTION> client state: CONNECTED > AUTHENTICATION
2025-03-01 20:02:28,364 - DEBUG - _bolt5.py:666 - [#FE31]  C: LOGON {'scheme': 'basic', 'principal': 'neo4j', 'credentials': '*******'}
2025-03-01 20:02:28,364 - DEBUG - _bolt5.py:100 - [#FE31]  _: <CONNECTION> client state: AUTHENTICATION > READY
2025-03-01 20:02:28,370 - DEBUG - _bolt5.py:484 - [#FE31]  S: SUCCESS {'server': 'Neo4j/5.24.0', 'connection_id': 'bolt-4', 'hints': {'connection.recv_timeout_seconds': 120}}
2025-03-01 20:02:28,371 - DEBUG - _bolt5.py:89 - [#FE31]  _: <CONNECTION> server state: CONNECTED > AUTHENTICATION
2025-03-01 20:02:28,375 - DEBUG - _bolt5.py:484 - [#FE31]  S: SUCCESS {}
2025-03-01 20:02:28,376 - DEBUG - _bolt5.py:89 - [#FE31]  _: <CONNECTION> server state: AUTHENTICATION > READY
2025-03-01 20:02:28,377 - DEBUG - _pool.py:501 - [#FE31]  _: <POOL> released bolt-4
2025-03-01 20:02:28,379 - INFO - database.py:16 - Connected to Neo4j database
2025-03-01 20:02:28,379 - INFO - app.py:86 - Database connection verified
2025-03-01 20:02:28,397 - INFO - app.py:93 - Starting Flask application...
2025-03-01 20:02:28,414 - WARNING - _internal.py:97 -  * Debugger is active!
2025-03-01 20:02:28,432 - INFO - _internal.py:97 -  * Debugger PIN: 128-764-036
2025-03-01 20:02:45,151 - INFO - _internal.py:97 - 127.0.0.1 - - [01/Mar/2025 20:02:45] "GET /admin HTTP/1.1" 200 -
2025-03-01 20:02:52,881 - DEBUG - workspace.py:230 - [#0000]  _: <WORKSPACE> routing towards fixed database: None
2025-03-01 20:02:52,882 - DEBUG - workspace.py:122 - [#0000]  _: <WORKSPACE> pinning database: None
2025-03-01 20:02:52,883 - DEBUG - _pool.py:655 - [#0000]  _: <POOL> acquire direct connection, access_mode='WRITE', database=AcquisitionDatabase(name=None, guessed=False)
2025-03-01 20:02:52,884 - DEBUG - _pool.py:355 - [#FE31]  _: <POOL> picked existing connection bolt-4
2025-03-01 20:02:52,885 - DEBUG - _pool.py:289 - [#FE31]  _: <POOL> checked re_auth auth=None updated=False force=False
2025-03-01 20:02:52,887 - DEBUG - _pool.py:379 - [#FE31]  _: <POOL> handing out existing connection
2025-03-01 20:02:52,888 - DEBUG - _bolt5.py:979 - [#FE31]  C: RUN 'MATCH (i:Image) RETURN i.path as path' {} {}
2025-03-01 20:02:52,889 - DEBUG - _bolt5.py:100 - [#FE31]  _: <CONNECTION> client state: READY > STREAMING
2025-03-01 20:02:52,891 - DEBUG - _bolt5.py:342 - [#FE31]  C: PULL {'n': 1000}
2025-03-01 20:02:53,642 - DEBUG - _bolt5.py:484 - [#FE31]  S: SUCCESS {'t_first': 746, 'fields': ['path']}
2025-03-01 20:02:53,643 - DEBUG - _bolt5.py:89 - [#FE31]  _: <CONNECTION> server state: READY > STREAMING
2025-03-01 20:02:53,653 - DEBUG - _bolt5.py:484 - [#FE31]  S: SUCCESS {'bookmark': 'FB:kcwQOrtZU/fhTzKzbDGEPMs6mMk2V5A=', 'statuses': [{'gql_status': '02000', 'status_description': 'note: no data'}], 'type': 'r', 't_last': 5, 'db': 'neo4j'}
2025-03-01 20:02:53,655 - DEBUG - _bolt5.py:89 - [#FE31]  _: <CONNECTION> server state: STREAMING > READY
2025-03-01 20:02:53,656 - DEBUG - _pool.py:501 - [#FE31]  _: <POOL> released bolt-4
2025-03-01 20:03:01,950 - DEBUG - workspace.py:230 - [#0000]  _: <WORKSPACE> routing towards fixed database: None
2025-03-01 20:03:01,951 - DEBUG - workspace.py:122 - [#0000]  _: <WORKSPACE> pinning database: None
2025-03-01 20:03:01,952 - DEBUG - _pool.py:655 - [#0000]  _: <POOL> acquire direct connection, access_mode='WRITE', database=AcquisitionDatabase(name=None, guessed=False)
2025-03-01 20:03:01,953 - DEBUG - _pool.py:355 - [#FE31]  _: <POOL> picked existing connection bolt-4
2025-03-01 20:03:01,954 - DEBUG - _pool.py:289 - [#FE31]  _: <POOL> checked re_auth auth=None updated=False force=False
2025-03-01 20:03:01,954 - DEBUG - _pool.py:379 - [#FE31]  _: <POOL> handing out existing connection
2025-03-01 20:03:01,955 - DEBUG - _bolt5.py:979 - [#FE31]  C: RUN 'MATCH (i:Image) RETURN i.path as path' {} {}
2025-03-01 20:03:01,957 - DEBUG - _bolt5.py:342 - [#FE31]  C: PULL {'n': 1000}
2025-03-01 20:03:01,988 - DEBUG - _bolt5.py:484 - [#FE31]  S: SUCCESS {'t_first': 25, 'fields': ['path']}
2025-03-01 20:03:01,990 - DEBUG - _bolt5.py:89 - [#FE31]  _: <CONNECTION> server state: READY > STREAMING
2025-03-01 20:03:01,998 - DEBUG - _bolt5.py:484 - [#FE31]  S: SUCCESS {'bookmark': 'FB:kcwQOrtZU/fhTzKzbDGEPMs6mMk2V5A=', 'statuses': [{'gql_status': '02000', 'status_description': 'note: no data'}], 'type': 'r', 't_last': 6, 'db': 'neo4j'}
2025-03-01 20:03:02,000 - DEBUG - _bolt5.py:89 - [#FE31]  _: <CONNECTION> server state: STREAMING > READY
2025-03-01 20:03:02,001 - DEBUG - _pool.py:501 - [#FE31]  _: <POOL> released bolt-4
2025-03-01 20:03:02,738 - DEBUG - workspace.py:230 - [#0000]  _: <WORKSPACE> routing towards fixed database: None
2025-03-01 20:03:02,739 - DEBUG - workspace.py:122 - [#0000]  _: <WORKSPACE> pinning database: None
2025-03-01 20:03:02,740 - DEBUG - _pool.py:655 - [#0000]  _: <POOL> acquire direct connection, access_mode='WRITE', database=AcquisitionDatabase(name=None, guessed=False)
2025-03-01 20:03:02,740 - DEBUG - _pool.py:355 - [#FE31]  _: <POOL> picked existing connection bolt-4
2025-03-01 20:03:02,741 - DEBUG - _pool.py:289 - [#FE31]  _: <POOL> checked re_auth auth=None updated=False force=False
2025-03-01 20:03:02,742 - DEBUG - _pool.py:379 - [#FE31]  _: <POOL> handing out existing connection
2025-03-01 20:03:02,743 - DEBUG - _bolt5.py:979 - [#FE31]  C: RUN 'MATCH (i:Image) RETURN i.path as path' {} {}
2025-03-01 20:03:02,743 - DEBUG - _bolt5.py:342 - [#FE31]  C: PULL {'n': 1000}
2025-03-01 20:03:02,772 - DEBUG - _bolt5.py:484 - [#FE31]  S: SUCCESS {'t_first': 13, 'fields': ['path']}
2025-03-01 20:03:02,773 - DEBUG - _bolt5.py:89 - [#FE31]  _: <CONNECTION> server state: READY > STREAMING
2025-03-01 20:03:02,782 - DEBUG - _bolt5.py:484 - [#FE31]  S: SUCCESS {'bookmark': 'FB:kcwQOrtZU/fhTzKzbDGEPMs6mMk2V5A=', 'statuses': [{'gql_status': '02000', 'status_description': 'note: no data'}], 'type': 'r', 't_last': 4, 'db': 'neo4j'}
2025-03-01 20:03:02,784 - DEBUG - _bolt5.py:89 - [#FE31]  _: <CONNECTION> server state: STREAMING > READY
2025-03-01 20:03:02,785 - DEBUG - _pool.py:501 - [#FE31]  _: <POOL> released bolt-4
2025-03-01 20:03:06,545 - DEBUG - workspace.py:230 - [#0000]  _: <WORKSPACE> routing towards fixed database: None
2025-03-01 20:03:06,547 - DEBUG - workspace.py:122 - [#0000]  _: <WORKSPACE> pinning database: None
2025-03-01 20:03:06,547 - DEBUG - _pool.py:655 - [#0000]  _: <POOL> acquire direct connection, access_mode='WRITE', database=AcquisitionDatabase(name=None, guessed=False)
2025-03-01 20:03:06,548 - DEBUG - _pool.py:355 - [#FE31]  _: <POOL> picked existing connection bolt-4
2025-03-01 20:03:06,551 - DEBUG - _pool.py:289 - [#FE31]  _: <POOL> checked re_auth auth=None updated=False force=False
2025-03-01 20:03:06,552 - DEBUG - _pool.py:379 - [#FE31]  _: <POOL> handing out existing connection
2025-03-01 20:03:06,554 - DEBUG - _bolt5.py:979 - [#FE31]  C: RUN 'MATCH (i:Image) RETURN i.path as path' {} {}
2025-03-01 20:03:06,555 - DEBUG - _bolt5.py:342 - [#FE31]  C: PULL {'n': 1000}
2025-03-01 20:03:06,570 - DEBUG - _bolt5.py:484 - [#FE31]  S: SUCCESS {'t_first': 9, 'fields': ['path']}
2025-03-01 20:03:06,571 - DEBUG - _bolt5.py:89 - [#FE31]  _: <CONNECTION> server state: READY > STREAMING
2025-03-01 20:03:06,577 - DEBUG - _bolt5.py:484 - [#FE31]  S: SUCCESS {'bookmark': 'FB:kcwQOrtZU/fhTzKzbDGEPMs6mMk2V5A=', 'statuses': [{'gql_status': '02000', 'status_description': 'note: no data'}], 'type': 'r', 't_last': 3, 'db': 'neo4j'}
2025-03-01 20:03:06,579 - DEBUG - _bolt5.py:89 - [#FE31]  _: <CONNECTION> server state: STREAMING > READY
2025-03-01 20:03:06,580 - DEBUG - _pool.py:501 - [#FE31]  _: <POOL> released bolt-4
2025-03-01 20:07:36,305 - INFO - _internal.py:97 -  * Restarting with stat
2025-03-01 20:07:36,868 - INFO - image_utils.py:94 - Generated placeholder image at placeholder.png
2025-03-01 20:07:36,869 - INFO - app.py:69 - Available images in C:\Users\alexa\dev\AiR-Helix-View\frontend\public\images:
2025-03-01 20:07:36,872 - INFO - app.py:74 -  - allianz_stadium_sydney01.jpg
2025-03-01 20:07:36,872 - INFO - app.py:74 -  - allianz_stadium_sydney03.jpg
2025-03-01 20:07:36,872 - INFO - app.py:74 -  - allianz_stadium_sydney05.jpg
2025-03-01 20:07:36,873 - INFO - app.py:74 -  - allianz_stadium_sydney10.jpg
2025-03-01 20:07:36,873 - INFO - app.py:74 -  - campbelltown_stadium04.jpg
2025-03-01 20:07:36,873 - INFO - app.py:74 -  - canberra_stadium01.jpg
2025-03-01 20:07:36,873 - INFO - app.py:74 -  - canberra_stadium02.jpg
2025-03-01 20:07:36,875 - INFO - app.py:74 -  - canberra_stadium03.jpg
2025-03-01 20:07:36,875 - INFO - app.py:74 -  - canberra_stadium04.jpg
2025-03-01 20:07:36,875 - INFO - app.py:74 -  - central_coast_stadium01.jpg
2025-03-01 20:07:36,880 - INFO - app.py:77 -  ... and 113 more images
2025-03-01 20:07:36,880 - INFO - app.py:78 - Total images found: 123
2025-03-01 20:07:44,447 - DEBUG - _pool.py:633 - [#0000]  _: <POOL> created, direct address IPv4Address(('localhost', 7687))
2025-03-01 20:07:44,448 - DEBUG - workspace.py:230 - [#0000]  _: <WORKSPACE> routing towards fixed database: None
2025-03-01 20:07:44,449 - DEBUG - workspace.py:122 - [#0000]  _: <WORKSPACE> pinning database: None
2025-03-01 20:07:44,449 - DEBUG - _pool.py:655 - [#0000]  _: <POOL> acquire direct connection, access_mode='READ', database=AcquisitionDatabase(name=None, guessed=False)
2025-03-01 20:07:44,449 - DEBUG - _pool.py:407 - [#0000]  _: <POOL> trying to hand out new connection
2025-03-01 20:07:44,450 - DEBUG - _util.py:178 - [#0000]  _: <RESOLVE> in: localhost:7687
2025-03-01 20:07:44,457 - DEBUG - _util.py:199 - [#0000]  _: <RESOLVE> dns resolver out: [::1]:7687
2025-03-01 20:07:44,458 - DEBUG - _bolt_socket.py:408 - [#0000]  C: <OPEN> [::1]:7687
2025-03-01 20:07:46,529 - DEBUG - _bolt_socket.py:420 - [#0000]  S: <ERROR> ConnectionRefusedError 10061 'No connection could be made because the target machine actively refused it' None 10061 None
2025-03-01 20:07:46,530 - DEBUG - _bolt_socket.py:457 - [#0000]  C: <CLOSE> [::1]:7687
2025-03-01 20:07:46,531 - DEBUG - _bolt_socket.py:343 - [#0000]  S: <CONNECTION FAILED> [::1]:7687 ServiceUnavailable: Failed to establish connection to ResolvedIPv6Address(('::1', 7687, 0, 0)) (reason [WinError 10061] No connection could be made because the target machine actively refused it)
2025-03-01 20:07:46,532 - DEBUG - _util.py:199 - [#0000]  _: <RESOLVE> dns resolver out: 127.0.0.1:7687
2025-03-01 20:07:46,533 - DEBUG - _bolt_socket.py:408 - [#0000]  C: <OPEN> 127.0.0.1:7687
2025-03-01 20:07:46,560 - DEBUG - _bolt_socket.py:239 - [#FFAF]  C: <MAGIC> 0x6060B017
2025-03-01 20:07:46,561 - DEBUG - _bolt_socket.py:244 - [#FFAF]  C: <HANDSHAKE> 0x000001FF 0x00080805 0x00020404 0x00000003
2025-03-01 20:07:46,563 - DEBUG - _bolt_socket.py:80 - [#FFAF]  S: <HANDSHAKE> 0x00000605
2025-03-01 20:07:46,565 - DEBUG - _bolt5.py:728 - [#FFAF]  C: HELLO {'user_agent': 'neo4j-python/5.28.1 Python/3.10.11-final-0 (win32)', 'bolt_agent': {'product': 'neo4j-python/5.28.1', 'platform': 'Windows 10; AMD64', 'language': 'Python/3.10.11-final-0', 'language_details': 'CPython; 3.10.11-final-0 (tags/v3.10.11:7d4cc5a, Apr  5 2023 00:38:17) [MSC v.1929 64 bit (AMD64)]'}}
2025-03-01 20:07:46,566 - DEBUG - _bolt5.py:100 - [#FFAF]  _: <CONNECTION> client state: CONNECTED > AUTHENTICATION
2025-03-01 20:07:46,567 - DEBUG - _bolt5.py:666 - [#FFAF]  C: LOGON {'scheme': 'basic', 'principal': 'neo4j', 'credentials': '*******'}
2025-03-01 20:07:46,567 - DEBUG - _bolt5.py:100 - [#FFAF]  _: <CONNECTION> client state: AUTHENTICATION > READY
2025-03-01 20:07:46,571 - DEBUG - _bolt5.py:484 - [#FFAF]  S: SUCCESS {'server': 'Neo4j/5.24.0', 'connection_id': 'bolt-5', 'hints': {'connection.recv_timeout_seconds': 120}}
2025-03-01 20:07:46,572 - DEBUG - _bolt5.py:89 - [#FFAF]  _: <CONNECTION> server state: CONNECTED > AUTHENTICATION
2025-03-01 20:07:46,579 - DEBUG - _bolt5.py:484 - [#FFAF]  S: SUCCESS {}
2025-03-01 20:07:46,580 - DEBUG - _bolt5.py:89 - [#FFAF]  _: <CONNECTION> server state: AUTHENTICATION > READY
2025-03-01 20:07:46,580 - DEBUG - _pool.py:501 - [#FFAF]  _: <POOL> released bolt-5
2025-03-01 20:07:46,581 - INFO - database.py:16 - Connected to Neo4j database
2025-03-01 20:07:46,581 - INFO - app.py:86 - Database connection verified
2025-03-01 20:07:46,592 - INFO - app.py:93 - Starting Flask application...
2025-03-01 20:07:46,603 - WARNING - _internal.py:97 -  * Debugger is active!
2025-03-01 20:07:46,613 - INFO - _internal.py:97 -  * Debugger PIN: 128-764-036
2025-03-01 20:07:54,893 - INFO - _internal.py:97 - 127.0.0.1 - - [01/Mar/2025 20:07:54] "GET /admin HTTP/1.1" 200 -
2025-03-01 20:18:08,493 - DEBUG - workspace.py:230 - [#0000]  _: <WORKSPACE> routing towards fixed database: None
2025-03-01 20:18:08,494 - DEBUG - workspace.py:122 - [#0000]  _: <WORKSPACE> pinning database: None
2025-03-01 20:18:08,494 - DEBUG - _pool.py:655 - [#0000]  _: <POOL> acquire direct connection, access_mode='WRITE', database=AcquisitionDatabase(name=None, guessed=False)
2025-03-01 20:18:08,495 - DEBUG - _pool.py:355 - [#FFAF]  _: <POOL> picked existing connection bolt-5
2025-03-01 20:18:08,495 - DEBUG - _pool.py:289 - [#FFAF]  _: <POOL> checked re_auth auth=None updated=False force=False
2025-03-01 20:18:08,495 - DEBUG - _pool.py:379 - [#FFAF]  _: <POOL> handing out existing connection
2025-03-01 20:18:08,498 - DEBUG - _bolt5.py:979 - [#FFAF]  C: RUN 'MATCH (i:Image) RETURN i.path as path' {} {}
2025-03-01 20:18:08,499 - DEBUG - _bolt5.py:100 - [#FFAF]  _: <CONNECTION> client state: READY > STREAMING
2025-03-01 20:18:08,499 - DEBUG - _bolt5.py:342 - [#FFAF]  C: PULL {'n': 1000}
2025-03-01 20:18:08,527 - DEBUG - _bolt5.py:484 - [#FFAF]  S: SUCCESS {'t_first': 22, 'fields': ['path']}
2025-03-01 20:18:08,528 - DEBUG - _bolt5.py:89 - [#FFAF]  _: <CONNECTION> server state: READY > STREAMING
2025-03-01 20:18:08,535 - DEBUG - _bolt5.py:484 - [#FFAF]  S: SUCCESS {'bookmark': 'FB:kcwQOrtZU/fhTzKzbDGEPMs6mMk2V5A=', 'statuses': [{'gql_status': '02000', 'status_description': 'note: no data'}], 'type': 'r', 't_last': 5, 'db': 'neo4j'}
2025-03-01 20:18:08,536 - DEBUG - _bolt5.py:89 - [#FFAF]  _: <CONNECTION> server state: STREAMING > READY
2025-03-01 20:18:08,537 - DEBUG - _pool.py:501 - [#FFAF]  _: <POOL> released bolt-5
2025-03-01 20:18:18,204 - DEBUG - workspace.py:230 - [#0000]  _: <WORKSPACE> routing towards fixed database: None
2025-03-01 20:18:18,204 - DEBUG - workspace.py:122 - [#0000]  _: <WORKSPACE> pinning database: None
2025-03-01 20:18:18,205 - DEBUG - _pool.py:655 - [#0000]  _: <POOL> acquire direct connection, access_mode='WRITE', database=AcquisitionDatabase(name=None, guessed=False)
2025-03-01 20:18:18,206 - DEBUG - _pool.py:355 - [#FFAF]  _: <POOL> picked existing connection bolt-5
2025-03-01 20:18:18,206 - DEBUG - _pool.py:289 - [#FFAF]  _: <POOL> checked re_auth auth=None updated=False force=False
2025-03-01 20:18:18,207 - DEBUG - _pool.py:379 - [#FFAF]  _: <POOL> handing out existing connection
2025-03-01 20:18:18,208 - DEBUG - _bolt5.py:979 - [#FFAF]  C: RUN 'MATCH (i:Image) RETURN i.path as path' {} {}
2025-03-01 20:18:18,209 - DEBUG - _bolt5.py:342 - [#FFAF]  C: PULL {'n': 1000}
2025-03-01 20:18:18,226 - DEBUG - _bolt5.py:484 - [#FFAF]  S: SUCCESS {'t_first': 12, 'fields': ['path']}
2025-03-01 20:18:18,227 - DEBUG - _bolt5.py:89 - [#FFAF]  _: <CONNECTION> server state: READY > STREAMING
2025-03-01 20:18:18,233 - DEBUG - _bolt5.py:484 - [#FFAF]  S: SUCCESS {'bookmark': 'FB:kcwQOrtZU/fhTzKzbDGEPMs6mMk2V5A=', 'statuses': [{'gql_status': '02000', 'status_description': 'note: no data'}], 'type': 'r', 't_last': 3, 'db': 'neo4j'}
2025-03-01 20:18:18,234 - DEBUG - _bolt5.py:89 - [#FFAF]  _: <CONNECTION> server state: STREAMING > READY
2025-03-01 20:18:18,235 - DEBUG - _pool.py:501 - [#FFAF]  _: <POOL> released bolt-5
2025-03-01 20:46:06,761 - DEBUG - workspace.py:230 - [#0000]  _: <WORKSPACE> routing towards fixed database: None
2025-03-01 20:46:06,762 - DEBUG - workspace.py:122 - [#0000]  _: <WORKSPACE> pinning database: None
2025-03-01 20:46:06,762 - DEBUG - _pool.py:655 - [#0000]  _: <POOL> acquire direct connection, access_mode='WRITE', database=AcquisitionDatabase(name=None, guessed=False)
2025-03-01 20:46:06,765 - DEBUG - _pool.py:355 - [#FFAF]  _: <POOL> picked existing connection bolt-5
2025-03-01 20:46:06,766 - DEBUG - _pool.py:289 - [#FFAF]  _: <POOL> checked re_auth auth=None updated=False force=False
2025-03-01 20:46:06,768 - DEBUG - _pool.py:379 - [#FFAF]  _: <POOL> handing out existing connection
2025-03-01 20:46:06,769 - DEBUG - _bolt5.py:979 - [#FFAF]  C: RUN 'MATCH (i:Image) RETURN i.path as path' {} {}
2025-03-01 20:46:06,770 - DEBUG - _bolt5.py:342 - [#FFAF]  C: PULL {'n': 1000}
2025-03-01 20:46:06,790 - DEBUG - _bolt5.py:484 - [#FFAF]  S: SUCCESS {'t_first': 16, 'fields': ['path']}
2025-03-01 20:46:06,791 - DEBUG - _bolt5.py:89 - [#FFAF]  _: <CONNECTION> server state: READY > STREAMING
2025-03-01 20:46:06,797 - DEBUG - _bolt5.py:484 - [#FFAF]  S: SUCCESS {'bookmark': 'FB:kcwQOrtZU/fhTzKzbDGEPMs6mMk2V5A=', 'statuses': [{'gql_status': '02000', 'status_description': 'note: no data'}], 'type': 'r', 't_last': 4, 'db': 'neo4j'}
2025-03-01 20:46:06,799 - DEBUG - _bolt5.py:89 - [#FFAF]  _: <CONNECTION> server state: STREAMING > READY
2025-03-01 20:46:06,799 - DEBUG - _pool.py:501 - [#FFAF]  _: <POOL> released bolt-5
2025-03-01 20:46:30,072 - DEBUG - workspace.py:230 - [#0000]  _: <WORKSPACE> routing towards fixed database: None
2025-03-01 20:46:30,073 - DEBUG - workspace.py:122 - [#0000]  _: <WORKSPACE> pinning database: None
2025-03-01 20:46:30,073 - DEBUG - _pool.py:655 - [#0000]  _: <POOL> acquire direct connection, access_mode='READ', database=AcquisitionDatabase(name=None, guessed=False)
2025-03-01 20:46:30,074 - DEBUG - _pool.py:355 - [#FFAF]  _: <POOL> picked existing connection bolt-5
2025-03-01 20:46:30,075 - DEBUG - _pool.py:289 - [#FFAF]  _: <POOL> checked re_auth auth=None updated=False force=False
2025-03-01 20:46:30,075 - DEBUG - _pool.py:379 - [#FFAF]  _: <POOL> handing out existing connection
2025-03-01 20:46:30,076 - DEBUG - _bolt5.py:1039 - [#FFAF]  C: BEGIN {'mode': 'r'}
2025-03-01 20:46:30,076 - DEBUG - _bolt5.py:100 - [#FFAF]  _: <CONNECTION> client state: STREAMING > TX_READY_OR_TX_STREAMING
2025-03-01 20:46:30,087 - DEBUG - _bolt5.py:484 - [#FFAF]  S: SUCCESS {}
2025-03-01 20:46:30,087 - DEBUG - _bolt5.py:89 - [#FFAF]  _: <CONNECTION> server state: READY > TX_READY_OR_TX_STREAMING
2025-03-01 20:46:30,088 - DEBUG - _bolt5.py:979 - [#FFAF]  C: RUN 'MATCH (i:Image {path: $image_path}) RETURN i' {'image_path': 'allianz_stadium_sydney01.jpg'} {}
2025-03-01 20:46:30,089 - DEBUG - _bolt5.py:342 - [#FFAF]  C: PULL {'n': 1000}
2025-03-01 20:46:30,289 - DEBUG - _bolt5.py:484 - [#FFAF]  S: SUCCESS {'t_first': 196, 'fields': ['i'], 'qid': 0}
2025-03-01 20:46:30,294 - DEBUG - _bolt5.py:484 - [#FFAF]  S: SUCCESS {'statuses': [{'gql_status': '02000', 'status_description': 'note: no data'}], 'type': 'r', 't_last': 4, 'db': 'neo4j'}
2025-03-01 20:46:30,300 - DEBUG - _bolt5.py:409 - [#FFAF]  C: COMMIT
2025-03-01 20:46:30,300 - DEBUG - _bolt5.py:100 - [#FFAF]  _: <CONNECTION> client state: TX_READY_OR_TX_STREAMING > READY
2025-03-01 20:46:30,304 - DEBUG - _bolt5.py:484 - [#FFAF]  S: SUCCESS {'bookmark': 'FB:kcwQOrtZU/fhTzKzbDGEPMs6mMk2V5A='}
2025-03-01 20:46:30,305 - DEBUG - _bolt5.py:89 - [#FFAF]  _: <CONNECTION> server state: TX_READY_OR_TX_STREAMING > READY
2025-03-01 20:46:30,305 - DEBUG - _pool.py:501 - [#FFAF]  _: <POOL> released bolt-5
2025-03-01 20:46:43,315 - DEBUG - workspace.py:230 - [#0000]  _: <WORKSPACE> routing towards fixed database: None
2025-03-01 20:46:43,317 - DEBUG - workspace.py:122 - [#0000]  _: <WORKSPACE> pinning database: None
2025-03-01 20:46:43,318 - DEBUG - _pool.py:655 - [#0000]  _: <POOL> acquire direct connection, access_mode='READ', database=AcquisitionDatabase(name=None, guessed=False)
2025-03-01 20:46:43,320 - DEBUG - _pool.py:340 - [#FFAF]  _: <POOL> liveness check
2025-03-01 20:46:43,321 - DEBUG - _bolt5.py:441 - [#FFAF]  C: RESET
2025-03-01 20:46:43,327 - DEBUG - _bolt5.py:484 - [#FFAF]  S: SUCCESS {}
2025-03-01 20:46:43,329 - DEBUG - _pool.py:355 - [#FFAF]  _: <POOL> picked existing connection bolt-5
2025-03-01 20:46:43,331 - DEBUG - _pool.py:289 - [#FFAF]  _: <POOL> checked re_auth auth=None updated=False force=False
2025-03-01 20:46:43,332 - DEBUG - _pool.py:379 - [#FFAF]  _: <POOL> handing out existing connection
2025-03-01 20:46:43,333 - DEBUG - _pool.py:501 - [#FFAF]  _: <POOL> released bolt-5
2025-03-01 20:46:43,333 - DEBUG - workspace.py:230 - [#0000]  _: <WORKSPACE> routing towards fixed database: None
2025-03-01 20:46:43,334 - DEBUG - workspace.py:122 - [#0000]  _: <WORKSPACE> pinning database: None
2025-03-01 20:46:43,335 - DEBUG - _pool.py:655 - [#0000]  _: <POOL> acquire direct connection, access_mode='WRITE', database=AcquisitionDatabase(name=None, guessed=False)
2025-03-01 20:46:43,337 - DEBUG - _pool.py:355 - [#FFAF]  _: <POOL> picked existing connection bolt-5
2025-03-01 20:46:43,338 - DEBUG - _pool.py:289 - [#FFAF]  _: <POOL> checked re_auth auth=None updated=False force=False
2025-03-01 20:46:43,339 - DEBUG - _pool.py:379 - [#FFAF]  _: <POOL> handing out existing connection
2025-03-01 20:46:43,341 - DEBUG - _bolt5.py:979 - [#FFAF]  C: RUN 'MATCH (i:Image) RETURN count(i) as count' {} {}
2025-03-01 20:46:43,342 - DEBUG - _bolt5.py:100 - [#FFAF]  _: <CONNECTION> client state: READY > STREAMING
2025-03-01 20:46:43,343 - DEBUG - _bolt5.py:342 - [#FFAF]  C: PULL {'n': 1000}
2025-03-01 20:46:43,554 - DEBUG - _bolt5.py:484 - [#FFAF]  S: SUCCESS {'t_first': 205, 'fields': ['count']}
2025-03-01 20:46:43,556 - DEBUG - _bolt5.py:89 - [#FFAF]  _: <CONNECTION> server state: READY > STREAMING
2025-03-01 20:46:43,562 - DEBUG - _bolt5.py:475 - [#FFAF]  S: RECORD * 1
2025-03-01 20:46:43,563 - DEBUG - _bolt5.py:484 - [#FFAF]  S: SUCCESS {'bookmark': 'FB:kcwQOrtZU/fhTzKzbDGEPMs6mMk2V5A=', 'statuses': [{'gql_status': '00000', 'status_description': 'note: successful completion'}], 'type': 'r', 't_last': 4, 'db': 'neo4j'}
2025-03-01 20:46:43,565 - DEBUG - _bolt5.py:89 - [#FFAF]  _: <CONNECTION> server state: STREAMING > READY
2025-03-01 20:46:43,566 - DEBUG - _pool.py:501 - [#FFAF]  _: <POOL> released bolt-5
2025-03-01 20:46:43,568 - DEBUG - workspace.py:230 - [#0000]  _: <WORKSPACE> routing towards fixed database: None
2025-03-01 20:46:43,569 - DEBUG - workspace.py:122 - [#0000]  _: <WORKSPACE> pinning database: None
2025-03-01 20:46:43,570 - DEBUG - _pool.py:655 - [#0000]  _: <POOL> acquire direct connection, access_mode='WRITE', database=AcquisitionDatabase(name=None, guessed=False)
2025-03-01 20:46:43,571 - DEBUG - _pool.py:355 - [#FFAF]  _: <POOL> picked existing connection bolt-5
2025-03-01 20:46:43,572 - DEBUG - _pool.py:289 - [#FFAF]  _: <POOL> checked re_auth auth=None updated=False force=False
2025-03-01 20:46:43,573 - DEBUG - _pool.py:379 - [#FFAF]  _: <POOL> handing out existing connection
2025-03-01 20:46:43,574 - DEBUG - _bolt5.py:979 - [#FFAF]  C: RUN 'MATCH (i:Image) RETURN i.path as path LIMIT $limit' {'limit': 10} {}
2025-03-01 20:46:43,576 - DEBUG - _bolt5.py:342 - [#FFAF]  C: PULL {'n': 1000}
2025-03-01 20:46:43,791 - DEBUG - _bolt5.py:484 - [#FFAF]  S: SUCCESS {'t_first': 211, 'fields': ['path']}
2025-03-01 20:46:43,793 - DEBUG - _bolt5.py:89 - [#FFAF]  _: <CONNECTION> server state: READY > STREAMING
2025-03-01 20:46:43,804 - DEBUG - _bolt5.py:484 - [#FFAF]  S: SUCCESS {'bookmark': 'FB:kcwQOrtZU/fhTzKzbDGEPMs6mMk2V5A=', 'statuses': [{'gql_status': '02000', 'status_description': 'note: no data'}], 'type': 'r', 't_last': 10, 'db': 'neo4j'}
2025-03-01 20:46:43,805 - DEBUG - _bolt5.py:89 - [#FFAF]  _: <CONNECTION> server state: STREAMING > READY
2025-03-01 20:46:43,806 - DEBUG - _pool.py:501 - [#FFAF]  _: <POOL> released bolt-5
2025-03-01 20:46:43,807 - DEBUG - workspace.py:230 - [#0000]  _: <WORKSPACE> routing towards fixed database: None
2025-03-01 20:46:43,807 - DEBUG - workspace.py:122 - [#0000]  _: <WORKSPACE> pinning database: None
2025-03-01 20:46:43,808 - DEBUG - _pool.py:655 - [#0000]  _: <POOL> acquire direct connection, access_mode='WRITE', database=AcquisitionDatabase(name=None, guessed=False)
2025-03-01 20:46:43,809 - DEBUG - _pool.py:355 - [#FFAF]  _: <POOL> picked existing connection bolt-5
2025-03-01 20:46:43,810 - DEBUG - _pool.py:289 - [#FFAF]  _: <POOL> checked re_auth auth=None updated=False force=False
2025-03-01 20:46:43,810 - DEBUG - _pool.py:379 - [#FFAF]  _: <POOL> handing out existing connection
2025-03-01 20:46:43,811 - DEBUG - _bolt5.py:979 - [#FFAF]  C: RUN 'MATCH (i:Image {path: $path}) RETURN i' {'path': 'allianz_stadium_sydney01.jpg'} {}
2025-03-01 20:46:43,811 - DEBUG - _bolt5.py:342 - [#FFAF]  C: PULL {'n': 1000}
2025-03-01 20:46:43,987 - DEBUG - _bolt5.py:484 - [#FFAF]  S: SUCCESS {'t_first': 171, 'fields': ['i']}
2025-03-01 20:46:43,987 - DEBUG - _bolt5.py:89 - [#FFAF]  _: <CONNECTION> server state: READY > STREAMING
2025-03-01 20:46:43,993 - DEBUG - _bolt5.py:484 - [#FFAF]  S: SUCCESS {'bookmark': 'FB:kcwQOrtZU/fhTzKzbDGEPMs6mMk2V5A=', 'statuses': [{'gql_status': '02000', 'status_description': 'note: no data'}], 'type': 'r', 't_last': 3, 'db': 'neo4j'}
2025-03-01 20:46:43,995 - DEBUG - _bolt5.py:89 - [#FFAF]  _: <CONNECTION> server state: STREAMING > READY
2025-03-01 20:46:43,996 - DEBUG - _pool.py:501 - [#FFAF]  _: <POOL> released bolt-5
2025-03-01 20:46:43,997 - DEBUG - workspace.py:230 - [#0000]  _: <WORKSPACE> routing towards fixed database: None
2025-03-01 20:46:43,998 - DEBUG - workspace.py:122 - [#0000]  _: <WORKSPACE> pinning database: None
2025-03-01 20:46:43,999 - DEBUG - _pool.py:655 - [#0000]  _: <POOL> acquire direct connection, access_mode='WRITE', database=AcquisitionDatabase(name=None, guessed=False)
2025-03-01 20:46:44,000 - DEBUG - _pool.py:355 - [#FFAF]  _: <POOL> picked existing connection bolt-5
2025-03-01 20:46:44,001 - DEBUG - _pool.py:289 - [#FFAF]  _: <POOL> checked re_auth auth=None updated=False force=False
2025-03-01 20:46:44,002 - DEBUG - _pool.py:379 - [#FFAF]  _: <POOL> handing out existing connection
2025-03-01 20:46:44,003 - DEBUG - _bolt5.py:979 - [#FFAF]  C: RUN 'MATCH (i:Image {path: $path}) RETURN i' {'path': 'images/allianz_stadium_sydney01.jpg'} {}
2025-03-01 20:46:44,005 - DEBUG - _bolt5.py:342 - [#FFAF]  C: PULL {'n': 1000}
2025-03-01 20:46:44,024 - DEBUG - _bolt5.py:484 - [#FFAF]  S: SUCCESS {'t_first': 14, 'fields': ['i']}
2025-03-01 20:46:44,026 - DEBUG - _bolt5.py:89 - [#FFAF]  _: <CONNECTION> server state: READY > STREAMING
2025-03-01 20:46:44,030 - DEBUG - _bolt5.py:484 - [#FFAF]  S: SUCCESS {'bookmark': 'FB:kcwQOrtZU/fhTzKzbDGEPMs6mMk2V5A=', 'statuses': [{'gql_status': '02000', 'status_description': 'note: no data'}], 'type': 'r', 't_last': 3, 'db': 'neo4j'}
2025-03-01 20:46:44,032 - DEBUG - _bolt5.py:89 - [#FFAF]  _: <CONNECTION> server state: STREAMING > READY
2025-03-01 20:46:44,033 - DEBUG - _pool.py:501 - [#FFAF]  _: <POOL> released bolt-5
2025-03-01 20:48:40,816 - INFO - image_utils.py:94 - Generated placeholder image at placeholder.png
2025-03-01 20:48:40,817 - INFO - app.py:69 - Available images in C:\Users\alexa\dev\AiR-Helix-View\frontend\public\images:
2025-03-01 20:48:40,818 - INFO - app.py:74 -  - allianz_stadium_sydney01.jpg
2025-03-01 20:48:40,819 - INFO - app.py:74 -  - allianz_stadium_sydney03.jpg
2025-03-01 20:48:40,819 - INFO - app.py:74 -  - allianz_stadium_sydney05.jpg
2025-03-01 20:48:40,819 - INFO - app.py:74 -  - allianz_stadium_sydney10.jpg
2025-03-01 20:48:40,820 - INFO - app.py:74 -  - campbelltown_stadium04.jpg
2025-03-01 20:48:40,820 - INFO - app.py:74 -  - canberra_stadium01.jpg
2025-03-01 20:48:40,820 - INFO - app.py:74 -  - canberra_stadium02.jpg
2025-03-01 20:48:40,821 - INFO - app.py:74 -  - canberra_stadium03.jpg
2025-03-01 20:48:40,822 - INFO - app.py:74 -  - canberra_stadium04.jpg
2025-03-01 20:48:40,822 - INFO - app.py:74 -  - central_coast_stadium01.jpg
2025-03-01 20:48:40,825 - INFO - app.py:77 -  ... and 113 more images
2025-03-01 20:48:40,825 - INFO - app.py:78 - Total images found: 123
2025-03-01 20:48:47,329 - DEBUG - _pool.py:633 - [#0000]  _: <POOL> created, direct address IPv4Address(('localhost', 7687))
2025-03-01 20:48:47,330 - DEBUG - workspace.py:230 - [#0000]  _: <WORKSPACE> routing towards fixed database: None
2025-03-01 20:48:47,331 - DEBUG - workspace.py:122 - [#0000]  _: <WORKSPACE> pinning database: None
2025-03-01 20:48:47,331 - DEBUG - _pool.py:655 - [#0000]  _: <POOL> acquire direct connection, access_mode='READ', database=AcquisitionDatabase(name=None, guessed=False)
2025-03-01 20:48:47,332 - DEBUG - _pool.py:407 - [#0000]  _: <POOL> trying to hand out new connection
2025-03-01 20:48:47,332 - DEBUG - _util.py:178 - [#0000]  _: <RESOLVE> in: localhost:7687
2025-03-01 20:48:47,336 - DEBUG - _util.py:199 - [#0000]  _: <RESOLVE> dns resolver out: [::1]:7687
2025-03-01 20:48:47,337 - DEBUG - _bolt_socket.py:408 - [#0000]  C: <OPEN> [::1]:7687
2025-03-01 20:48:49,390 - DEBUG - _bolt_socket.py:420 - [#0000]  S: <ERROR> ConnectionRefusedError 10061 'No connection could be made because the target machine actively refused it' None 10061 None
2025-03-01 20:48:49,391 - DEBUG - _bolt_socket.py:457 - [#0000]  C: <CLOSE> [::1]:7687
2025-03-01 20:48:49,392 - DEBUG - _bolt_socket.py:343 - [#0000]  S: <CONNECTION FAILED> [::1]:7687 ServiceUnavailable: Failed to establish connection to ResolvedIPv6Address(('::1', 7687, 0, 0)) (reason [WinError 10061] No connection could be made because the target machine actively refused it)
2025-03-01 20:48:49,394 - DEBUG - _util.py:199 - [#0000]  _: <RESOLVE> dns resolver out: 127.0.0.1:7687
2025-03-01 20:48:49,395 - DEBUG - _bolt_socket.py:408 - [#0000]  C: <OPEN> 127.0.0.1:7687
2025-03-01 20:48:49,397 - DEBUG - _bolt_socket.py:239 - [#C5D6]  C: <MAGIC> 0x6060B017
2025-03-01 20:48:49,398 - DEBUG - _bolt_socket.py:244 - [#C5D6]  C: <HANDSHAKE> 0x000001FF 0x00080805 0x00020404 0x00000003
2025-03-01 20:48:49,402 - DEBUG - _bolt_socket.py:80 - [#C5D6]  S: <HANDSHAKE> 0x00000605
2025-03-01 20:48:49,403 - DEBUG - _bolt5.py:728 - [#C5D6]  C: HELLO {'user_agent': 'neo4j-python/5.28.1 Python/3.10.11-final-0 (win32)', 'bolt_agent': {'product': 'neo4j-python/5.28.1', 'platform': 'Windows 10; AMD64', 'language': 'Python/3.10.11-final-0', 'language_details': 'CPython; 3.10.11-final-0 (tags/v3.10.11:7d4cc5a, Apr  5 2023 00:38:17) [MSC v.1929 64 bit (AMD64)]'}}
2025-03-01 20:48:49,405 - DEBUG - _bolt5.py:100 - [#C5D6]  _: <CONNECTION> client state: CONNECTED > AUTHENTICATION
2025-03-01 20:48:49,406 - DEBUG - _bolt5.py:666 - [#C5D6]  C: LOGON {'scheme': 'basic', 'principal': 'neo4j', 'credentials': '*******'}
2025-03-01 20:48:49,407 - DEBUG - _bolt5.py:100 - [#C5D6]  _: <CONNECTION> client state: AUTHENTICATION > READY
2025-03-01 20:48:49,411 - DEBUG - _bolt5.py:484 - [#C5D6]  S: SUCCESS {'server': 'Neo4j/5.24.0', 'connection_id': 'bolt-6', 'hints': {'connection.recv_timeout_seconds': 120}}
2025-03-01 20:48:49,412 - DEBUG - _bolt5.py:89 - [#C5D6]  _: <CONNECTION> server state: CONNECTED > AUTHENTICATION
2025-03-01 20:48:49,425 - DEBUG - _bolt5.py:484 - [#C5D6]  S: SUCCESS {}
2025-03-01 20:48:49,426 - DEBUG - _bolt5.py:89 - [#C5D6]  _: <CONNECTION> server state: AUTHENTICATION > READY
2025-03-01 20:48:49,427 - DEBUG - _pool.py:501 - [#C5D6]  _: <POOL> released bolt-6
2025-03-01 20:48:49,428 - INFO - database.py:16 - Connected to Neo4j database
2025-03-01 20:48:49,429 - INFO - app.py:86 - Database connection verified
2025-03-01 20:48:49,448 - INFO - app.py:93 - Starting Flask application...
2025-03-01 20:48:49,477 - INFO - _internal.py:97 - [31m[1mWARNING: This is a development server. Do not use it in a production deployment. Use a production WSGI server instead.[0m
 * Running on http://127.0.0.1:5001
2025-03-01 20:48:49,479 - INFO - _internal.py:97 - [33mPress CTRL+C to quit[0m
2025-03-01 20:48:49,483 - INFO - _internal.py:97 -  * Restarting with stat
2025-03-01 20:48:50,011 - INFO - image_utils.py:94 - Generated placeholder image at placeholder.png
2025-03-01 20:48:50,012 - INFO - app.py:69 - Available images in C:\Users\alexa\dev\AiR-Helix-View\frontend\public\images:
2025-03-01 20:48:50,014 - INFO - app.py:74 -  - allianz_stadium_sydney01.jpg
2025-03-01 20:48:50,015 - INFO - app.py:74 -  - allianz_stadium_sydney03.jpg
2025-03-01 20:48:50,016 - INFO - app.py:74 -  - allianz_stadium_sydney05.jpg
2025-03-01 20:48:50,016 - INFO - app.py:74 -  - allianz_stadium_sydney10.jpg
2025-03-01 20:48:50,016 - INFO - app.py:74 -  - campbelltown_stadium04.jpg
2025-03-01 20:48:50,017 - INFO - app.py:74 -  - canberra_stadium01.jpg
2025-03-01 20:48:50,017 - INFO - app.py:74 -  - canberra_stadium02.jpg
2025-03-01 20:48:50,018 - INFO - app.py:74 -  - canberra_stadium03.jpg
2025-03-01 20:48:50,018 - INFO - app.py:74 -  - canberra_stadium04.jpg
2025-03-01 20:48:50,019 - INFO - app.py:74 -  - central_coast_stadium01.jpg
2025-03-01 20:48:50,023 - INFO - app.py:77 -  ... and 113 more images
2025-03-01 20:48:50,024 - INFO - app.py:78 - Total images found: 123
2025-03-01 20:48:58,684 - DEBUG - _pool.py:633 - [#0000]  _: <POOL> created, direct address IPv4Address(('localhost', 7687))
2025-03-01 20:48:58,685 - DEBUG - workspace.py:230 - [#0000]  _: <WORKSPACE> routing towards fixed database: None
2025-03-01 20:48:58,686 - DEBUG - workspace.py:122 - [#0000]  _: <WORKSPACE> pinning database: None
2025-03-01 20:48:58,687 - DEBUG - _pool.py:655 - [#0000]  _: <POOL> acquire direct connection, access_mode='READ', database=AcquisitionDatabase(name=None, guessed=False)
2025-03-01 20:48:58,688 - DEBUG - _pool.py:407 - [#0000]  _: <POOL> trying to hand out new connection
2025-03-01 20:48:58,688 - DEBUG - _util.py:178 - [#0000]  _: <RESOLVE> in: localhost:7687
2025-03-01 20:48:58,696 - DEBUG - _util.py:199 - [#0000]  _: <RESOLVE> dns resolver out: [::1]:7687
2025-03-01 20:48:58,698 - DEBUG - _bolt_socket.py:408 - [#0000]  C: <OPEN> [::1]:7687
2025-03-01 20:49:00,737 - DEBUG - _bolt_socket.py:420 - [#0000]  S: <ERROR> ConnectionRefusedError 10061 'No connection could be made because the target machine actively refused it' None 10061 None
2025-03-01 20:49:00,738 - DEBUG - _bolt_socket.py:457 - [#0000]  C: <CLOSE> [::1]:7687
2025-03-01 20:49:00,739 - DEBUG - _bolt_socket.py:343 - [#0000]  S: <CONNECTION FAILED> [::1]:7687 ServiceUnavailable: Failed to establish connection to ResolvedIPv6Address(('::1', 7687, 0, 0)) (reason [WinError 10061] No connection could be made because the target machine actively refused it)
2025-03-01 20:49:00,740 - DEBUG - _util.py:199 - [#0000]  _: <RESOLVE> dns resolver out: 127.0.0.1:7687
2025-03-01 20:49:00,743 - DEBUG - _bolt_socket.py:408 - [#0000]  C: <OPEN> 127.0.0.1:7687
2025-03-01 20:49:00,767 - DEBUG - _bolt_socket.py:239 - [#C5E8]  C: <MAGIC> 0x6060B017
2025-03-01 20:49:00,768 - DEBUG - _bolt_socket.py:244 - [#C5E8]  C: <HANDSHAKE> 0x000001FF 0x00080805 0x00020404 0x00000003
2025-03-01 20:49:00,772 - DEBUG - _bolt_socket.py:80 - [#C5E8]  S: <HANDSHAKE> 0x00000605
2025-03-01 20:49:00,774 - DEBUG - _bolt5.py:728 - [#C5E8]  C: HELLO {'user_agent': 'neo4j-python/5.28.1 Python/3.10.11-final-0 (win32)', 'bolt_agent': {'product': 'neo4j-python/5.28.1', 'platform': 'Windows 10; AMD64', 'language': 'Python/3.10.11-final-0', 'language_details': 'CPython; 3.10.11-final-0 (tags/v3.10.11:7d4cc5a, Apr  5 2023 00:38:17) [MSC v.1929 64 bit (AMD64)]'}}
2025-03-01 20:49:00,776 - DEBUG - _bolt5.py:100 - [#C5E8]  _: <CONNECTION> client state: CONNECTED > AUTHENTICATION
2025-03-01 20:49:00,777 - DEBUG - _bolt5.py:666 - [#C5E8]  C: LOGON {'scheme': 'basic', 'principal': 'neo4j', 'credentials': '*******'}
2025-03-01 20:49:00,778 - DEBUG - _bolt5.py:100 - [#C5E8]  _: <CONNECTION> client state: AUTHENTICATION > READY
2025-03-01 20:49:00,782 - DEBUG - _bolt5.py:484 - [#C5E8]  S: SUCCESS {'server': 'Neo4j/5.24.0', 'connection_id': 'bolt-7', 'hints': {'connection.recv_timeout_seconds': 120}}
2025-03-01 20:49:00,784 - DEBUG - _bolt5.py:89 - [#C5E8]  _: <CONNECTION> server state: CONNECTED > AUTHENTICATION
2025-03-01 20:49:00,787 - DEBUG - _bolt5.py:484 - [#C5E8]  S: SUCCESS {}
2025-03-01 20:49:00,788 - DEBUG - _bolt5.py:89 - [#C5E8]  _: <CONNECTION> server state: AUTHENTICATION > READY
2025-03-01 20:49:00,791 - DEBUG - _pool.py:501 - [#C5E8]  _: <POOL> released bolt-7
2025-03-01 20:49:00,792 - INFO - database.py:16 - Connected to Neo4j database
2025-03-01 20:49:00,792 - INFO - app.py:86 - Database connection verified
2025-03-01 20:49:00,804 - INFO - app.py:93 - Starting Flask application...
2025-03-01 20:49:00,816 - WARNING - _internal.py:97 -  * Debugger is active!
2025-03-01 20:49:00,828 - INFO - _internal.py:97 -  * Debugger PIN: 128-764-036
2025-03-01 20:49:43,592 - DEBUG - workspace.py:230 - [#0000]  _: <WORKSPACE> routing towards fixed database: None
2025-03-01 20:49:43,593 - DEBUG - workspace.py:122 - [#0000]  _: <WORKSPACE> pinning database: None
2025-03-01 20:49:43,596 - DEBUG - _pool.py:655 - [#0000]  _: <POOL> acquire direct connection, access_mode='READ', database=AcquisitionDatabase(name=None, guessed=False)
2025-03-01 20:49:43,598 - DEBUG - _pool.py:355 - [#C5E8]  _: <POOL> picked existing connection bolt-7
2025-03-01 20:49:43,600 - DEBUG - _pool.py:289 - [#C5E8]  _: <POOL> checked re_auth auth=None updated=False force=False
2025-03-01 20:49:43,601 - DEBUG - _pool.py:379 - [#C5E8]  _: <POOL> handing out existing connection
2025-03-01 20:49:43,603 - DEBUG - _bolt5.py:1039 - [#C5E8]  C: BEGIN {'mode': 'r'}
2025-03-01 20:49:43,606 - DEBUG - _bolt5.py:100 - [#C5E8]  _: <CONNECTION> client state: READY > TX_READY_OR_TX_STREAMING
2025-03-01 20:49:43,619 - DEBUG - _bolt5.py:484 - [#C5E8]  S: SUCCESS {}
2025-03-01 20:49:43,619 - DEBUG - _bolt5.py:89 - [#C5E8]  _: <CONNECTION> server state: READY > TX_READY_OR_TX_STREAMING
2025-03-01 20:49:43,620 - DEBUG - _bolt5.py:979 - [#C5E8]  C: RUN 'MATCH (i:Image {path: $image_path}) RETURN i' {'image_path': 'allianz_stadium_sydney01.jpg'} {}
2025-03-01 20:49:43,622 - DEBUG - _bolt5.py:342 - [#C5E8]  C: PULL {'n': 1000}
2025-03-01 20:49:43,632 - DEBUG - _bolt5.py:484 - [#C5E8]  S: SUCCESS {'t_first': 7, 'fields': ['i'], 'qid': 0}
2025-03-01 20:49:43,638 - DEBUG - _bolt5.py:484 - [#C5E8]  S: SUCCESS {'statuses': [{'gql_status': '02000', 'status_description': 'note: no data'}], 'type': 'r', 't_last': 3, 'db': 'neo4j'}
2025-03-01 20:49:43,640 - DEBUG - _bolt5.py:409 - [#C5E8]  C: COMMIT
2025-03-01 20:49:43,642 - DEBUG - _bolt5.py:100 - [#C5E8]  _: <CONNECTION> client state: TX_READY_OR_TX_STREAMING > READY
2025-03-01 20:49:43,645 - DEBUG - _bolt5.py:484 - [#C5E8]  S: SUCCESS {'bookmark': 'FB:kcwQOrtZU/fhTzKzbDGEPMs6mMk2V5A='}
2025-03-01 20:49:43,647 - DEBUG - _bolt5.py:89 - [#C5E8]  _: <CONNECTION> server state: TX_READY_OR_TX_STREAMING > READY
2025-03-01 20:49:43,648 - DEBUG - _pool.py:501 - [#C5E8]  _: <POOL> released bolt-7
2025-03-01 20:53:11,761 - INFO - image_utils.py:94 - Generated placeholder image at placeholder.png
2025-03-01 20:53:11,762 - INFO - app.py:69 - Available images in C:\Users\alexa\dev\AiR-Helix-View\frontend\public\images:
2025-03-01 20:53:11,764 - INFO - app.py:74 -  - allianz_stadium_sydney01.jpg
2025-03-01 20:53:11,764 - INFO - app.py:74 -  - allianz_stadium_sydney03.jpg
2025-03-01 20:53:11,765 - INFO - app.py:74 -  - allianz_stadium_sydney05.jpg
2025-03-01 20:53:11,765 - INFO - app.py:74 -  - allianz_stadium_sydney10.jpg
2025-03-01 20:53:11,765 - INFO - app.py:74 -  - campbelltown_stadium04.jpg
2025-03-01 20:53:11,765 - INFO - app.py:74 -  - canberra_stadium01.jpg
2025-03-01 20:53:11,766 - INFO - app.py:74 -  - canberra_stadium02.jpg
2025-03-01 20:53:11,766 - INFO - app.py:74 -  - canberra_stadium03.jpg
2025-03-01 20:53:11,766 - INFO - app.py:74 -  - canberra_stadium04.jpg
2025-03-01 20:53:11,766 - INFO - app.py:74 -  - central_coast_stadium01.jpg
2025-03-01 20:53:11,769 - INFO - app.py:77 -  ... and 113 more images
2025-03-01 20:53:11,769 - INFO - app.py:78 - Total images found: 123
2025-03-01 20:53:18,108 - DEBUG - _pool.py:633 - [#0000]  _: <POOL> created, direct address IPv4Address(('localhost', 7687))
2025-03-01 20:53:18,110 - DEBUG - workspace.py:230 - [#0000]  _: <WORKSPACE> routing towards fixed database: None
2025-03-01 20:53:18,110 - DEBUG - workspace.py:122 - [#0000]  _: <WORKSPACE> pinning database: None
2025-03-01 20:53:18,111 - DEBUG - _pool.py:655 - [#0000]  _: <POOL> acquire direct connection, access_mode='READ', database=AcquisitionDatabase(name=None, guessed=False)
2025-03-01 20:53:18,111 - DEBUG - _pool.py:407 - [#0000]  _: <POOL> trying to hand out new connection
2025-03-01 20:53:18,112 - DEBUG - _util.py:178 - [#0000]  _: <RESOLVE> in: localhost:7687
2025-03-01 20:53:18,116 - DEBUG - _util.py:199 - [#0000]  _: <RESOLVE> dns resolver out: [::1]:7687
2025-03-01 20:53:18,117 - DEBUG - _bolt_socket.py:408 - [#0000]  C: <OPEN> [::1]:7687
2025-03-01 20:53:20,164 - DEBUG - _bolt_socket.py:420 - [#0000]  S: <ERROR> ConnectionRefusedError 10061 'No connection could be made because the target machine actively refused it' None 10061 None
2025-03-01 20:53:20,166 - DEBUG - _bolt_socket.py:457 - [#0000]  C: <CLOSE> [::1]:7687
2025-03-01 20:53:20,167 - DEBUG - _bolt_socket.py:343 - [#0000]  S: <CONNECTION FAILED> [::1]:7687 ServiceUnavailable: Failed to establish connection to ResolvedIPv6Address(('::1', 7687, 0, 0)) (reason [WinError 10061] No connection could be made because the target machine actively refused it)
2025-03-01 20:53:20,168 - DEBUG - _util.py:199 - [#0000]  _: <RESOLVE> dns resolver out: 127.0.0.1:7687
2025-03-01 20:53:20,170 - DEBUG - _bolt_socket.py:408 - [#0000]  C: <OPEN> 127.0.0.1:7687
2025-03-01 20:53:20,195 - DEBUG - _bolt_socket.py:239 - [#C726]  C: <MAGIC> 0x6060B017
2025-03-01 20:53:20,196 - DEBUG - _bolt_socket.py:244 - [#C726]  C: <HANDSHAKE> 0x000001FF 0x00080805 0x00020404 0x00000003
2025-03-01 20:53:20,201 - DEBUG - _bolt_socket.py:80 - [#C726]  S: <HANDSHAKE> 0x00000605
2025-03-01 20:53:20,202 - DEBUG - _bolt5.py:728 - [#C726]  C: HELLO {'user_agent': 'neo4j-python/5.28.1 Python/3.10.11-final-0 (win32)', 'bolt_agent': {'product': 'neo4j-python/5.28.1', 'platform': 'Windows 10; AMD64', 'language': 'Python/3.10.11-final-0', 'language_details': 'CPython; 3.10.11-final-0 (tags/v3.10.11:7d4cc5a, Apr  5 2023 00:38:17) [MSC v.1929 64 bit (AMD64)]'}}
2025-03-01 20:53:20,204 - DEBUG - _bolt5.py:100 - [#C726]  _: <CONNECTION> client state: CONNECTED > AUTHENTICATION
2025-03-01 20:53:20,205 - DEBUG - _bolt5.py:666 - [#C726]  C: LOGON {'scheme': 'basic', 'principal': 'neo4j', 'credentials': '*******'}
2025-03-01 20:53:20,206 - DEBUG - _bolt5.py:100 - [#C726]  _: <CONNECTION> client state: AUTHENTICATION > READY
2025-03-01 20:53:20,212 - DEBUG - _bolt5.py:484 - [#C726]  S: SUCCESS {'server': 'Neo4j/5.24.0', 'connection_id': 'bolt-8', 'hints': {'connection.recv_timeout_seconds': 120}}
2025-03-01 20:53:20,213 - DEBUG - _bolt5.py:89 - [#C726]  _: <CONNECTION> server state: CONNECTED > AUTHENTICATION
2025-03-01 20:53:20,216 - DEBUG - _bolt5.py:484 - [#C726]  S: SUCCESS {}
2025-03-01 20:53:20,217 - DEBUG - _bolt5.py:89 - [#C726]  _: <CONNECTION> server state: AUTHENTICATION > READY
2025-03-01 20:53:20,218 - DEBUG - _pool.py:501 - [#C726]  _: <POOL> released bolt-8
2025-03-01 20:53:20,219 - INFO - database.py:16 - Connected to Neo4j database
2025-03-01 20:53:20,219 - INFO - app.py:86 - Database connection verified
2025-03-01 20:53:20,232 - INFO - app.py:93 - Starting Flask application...
2025-03-01 20:53:20,261 - INFO - _internal.py:97 - [31m[1mWARNING: This is a development server. Do not use it in a production deployment. Use a production WSGI server instead.[0m
 * Running on http://127.0.0.1:5001
2025-03-01 20:53:20,262 - INFO - _internal.py:97 - [33mPress CTRL+C to quit[0m
2025-03-01 20:53:20,265 - INFO - _internal.py:97 -  * Restarting with stat
2025-03-01 20:53:20,729 - INFO - image_utils.py:94 - Generated placeholder image at placeholder.png
2025-03-01 20:53:20,730 - INFO - app.py:69 - Available images in C:\Users\alexa\dev\AiR-Helix-View\frontend\public\images:
2025-03-01 20:53:20,732 - INFO - app.py:74 -  - allianz_stadium_sydney01.jpg
2025-03-01 20:53:20,733 - INFO - app.py:74 -  - allianz_stadium_sydney03.jpg
2025-03-01 20:53:20,733 - INFO - app.py:74 -  - allianz_stadium_sydney05.jpg
2025-03-01 20:53:20,734 - INFO - app.py:74 -  - allianz_stadium_sydney10.jpg
2025-03-01 20:53:20,734 - INFO - app.py:74 -  - campbelltown_stadium04.jpg
2025-03-01 20:53:20,734 - INFO - app.py:74 -  - canberra_stadium01.jpg
2025-03-01 20:53:20,734 - INFO - app.py:74 -  - canberra_stadium02.jpg
2025-03-01 20:53:20,735 - INFO - app.py:74 -  - canberra_stadium03.jpg
2025-03-01 20:53:20,735 - INFO - app.py:74 -  - canberra_stadium04.jpg
2025-03-01 20:53:20,735 - INFO - app.py:74 -  - central_coast_stadium01.jpg
2025-03-01 20:53:20,738 - INFO - app.py:77 -  ... and 113 more images
2025-03-01 20:53:20,739 - INFO - app.py:78 - Total images found: 123
2025-03-01 20:53:27,329 - DEBUG - _pool.py:633 - [#0000]  _: <POOL> created, direct address IPv4Address(('localhost', 7687))
2025-03-01 20:53:27,330 - DEBUG - workspace.py:230 - [#0000]  _: <WORKSPACE> routing towards fixed database: None
2025-03-01 20:53:27,331 - DEBUG - workspace.py:122 - [#0000]  _: <WORKSPACE> pinning database: None
2025-03-01 20:53:27,332 - DEBUG - _pool.py:655 - [#0000]  _: <POOL> acquire direct connection, access_mode='READ', database=AcquisitionDatabase(name=None, guessed=False)
2025-03-01 20:53:27,333 - DEBUG - _pool.py:407 - [#0000]  _: <POOL> trying to hand out new connection
2025-03-01 20:53:27,333 - DEBUG - _util.py:178 - [#0000]  _: <RESOLVE> in: localhost:7687
2025-03-01 20:53:27,338 - DEBUG - _util.py:199 - [#0000]  _: <RESOLVE> dns resolver out: [::1]:7687
2025-03-01 20:53:27,339 - DEBUG - _bolt_socket.py:408 - [#0000]  C: <OPEN> [::1]:7687
2025-03-01 20:53:29,390 - DEBUG - _bolt_socket.py:420 - [#0000]  S: <ERROR> ConnectionRefusedError 10061 'No connection could be made because the target machine actively refused it' None 10061 None
2025-03-01 20:53:29,391 - DEBUG - _bolt_socket.py:457 - [#0000]  C: <CLOSE> [::1]:7687
2025-03-01 20:53:29,392 - DEBUG - _bolt_socket.py:343 - [#0000]  S: <CONNECTION FAILED> [::1]:7687 ServiceUnavailable: Failed to establish connection to ResolvedIPv6Address(('::1', 7687, 0, 0)) (reason [WinError 10061] No connection could be made because the target machine actively refused it)
2025-03-01 20:53:29,392 - DEBUG - _util.py:199 - [#0000]  _: <RESOLVE> dns resolver out: 127.0.0.1:7687
2025-03-01 20:53:29,394 - DEBUG - _bolt_socket.py:408 - [#0000]  C: <OPEN> 127.0.0.1:7687
2025-03-01 20:53:29,405 - DEBUG - _bolt_socket.py:239 - [#C733]  C: <MAGIC> 0x6060B017
2025-03-01 20:53:29,406 - DEBUG - _bolt_socket.py:244 - [#C733]  C: <HANDSHAKE> 0x000001FF 0x00080805 0x00020404 0x00000003
2025-03-01 20:53:29,409 - DEBUG - _bolt_socket.py:80 - [#C733]  S: <HANDSHAKE> 0x00000605
2025-03-01 20:53:29,411 - DEBUG - _bolt5.py:728 - [#C733]  C: HELLO {'user_agent': 'neo4j-python/5.28.1 Python/3.10.11-final-0 (win32)', 'bolt_agent': {'product': 'neo4j-python/5.28.1', 'platform': 'Windows 10; AMD64', 'language': 'Python/3.10.11-final-0', 'language_details': 'CPython; 3.10.11-final-0 (tags/v3.10.11:7d4cc5a, Apr  5 2023 00:38:17) [MSC v.1929 64 bit (AMD64)]'}}
2025-03-01 20:53:29,413 - DEBUG - _bolt5.py:100 - [#C733]  _: <CONNECTION> client state: CONNECTED > AUTHENTICATION
2025-03-01 20:53:29,414 - DEBUG - _bolt5.py:666 - [#C733]  C: LOGON {'scheme': 'basic', 'principal': 'neo4j', 'credentials': '*******'}
2025-03-01 20:53:29,415 - DEBUG - _bolt5.py:100 - [#C733]  _: <CONNECTION> client state: AUTHENTICATION > READY
2025-03-01 20:53:29,419 - DEBUG - _bolt5.py:484 - [#C733]  S: SUCCESS {'server': 'Neo4j/5.24.0', 'connection_id': 'bolt-9', 'hints': {'connection.recv_timeout_seconds': 120}}
2025-03-01 20:53:29,421 - DEBUG - _bolt5.py:89 - [#C733]  _: <CONNECTION> server state: CONNECTED > AUTHENTICATION
2025-03-01 20:53:29,426 - DEBUG - _bolt5.py:484 - [#C733]  S: SUCCESS {}
2025-03-01 20:53:29,427 - DEBUG - _bolt5.py:89 - [#C733]  _: <CONNECTION> server state: AUTHENTICATION > READY
2025-03-01 20:53:29,428 - DEBUG - _pool.py:501 - [#C733]  _: <POOL> released bolt-9
2025-03-01 20:53:29,430 - INFO - database.py:16 - Connected to Neo4j database
2025-03-01 20:53:29,430 - INFO - app.py:86 - Database connection verified
2025-03-01 20:53:29,446 - INFO - app.py:93 - Starting Flask application...
2025-03-01 20:53:29,462 - WARNING - _internal.py:97 -  * Debugger is active!
2025-03-01 20:53:29,473 - INFO - _internal.py:97 -  * Debugger PIN: 128-764-036
2025-03-01 20:54:24,264 - ERROR - app.py:47 - Unhandled exception: 404 Not Found: The requested URL was not found on the server. If you entered the URL manually please check your spelling and try again.
2025-03-01 20:54:24,268 - DEBUG - workspace.py:230 - [#0000]  _: <WORKSPACE> routing towards fixed database: None
2025-03-01 20:54:24,270 - DEBUG - workspace.py:122 - [#0000]  _: <WORKSPACE> pinning database: None
2025-03-01 20:54:24,270 - DEBUG - _pool.py:655 - [#0000]  _: <POOL> acquire direct connection, access_mode='READ', database=AcquisitionDatabase(name=None, guessed=False)
2025-03-01 20:54:24,271 - DEBUG - _pool.py:355 - [#C733]  _: <POOL> picked existing connection bolt-9
2025-03-01 20:54:24,273 - DEBUG - _pool.py:289 - [#C733]  _: <POOL> checked re_auth auth=None updated=False force=False
2025-03-01 20:54:24,273 - ERROR - app.py:47 - Unhandled exception: 404 Not Found: The requested URL was not found on the server. If you entered the URL manually please check your spelling and try again.
2025-03-01 20:54:24,274 - DEBUG - _pool.py:379 - [#C733]  _: <POOL> handing out existing connection
2025-03-01 20:54:24,275 - DEBUG - _bolt5.py:1039 - [#C733]  C: BEGIN {'mode': 'r'}
2025-03-01 20:54:24,276 - DEBUG - _bolt5.py:100 - [#C733]  _: <CONNECTION> client state: READY > TX_READY_OR_TX_STREAMING
2025-03-01 20:54:24,284 - DEBUG - _bolt5.py:484 - [#C733]  S: SUCCESS {}
2025-03-01 20:54:24,284 - DEBUG - _bolt5.py:89 - [#C733]  _: <CONNECTION> server state: READY > TX_READY_OR_TX_STREAMING
2025-03-01 20:54:24,286 - DEBUG - _bolt5.py:979 - [#C733]  C: RUN 'MATCH (i:Image {path: $image_path}) RETURN i' {'image_path': 'allianz_stadium_sydney01.jpg'} {}
2025-03-01 20:54:24,287 - DEBUG - _bolt5.py:342 - [#C733]  C: PULL {'n': 1000}
2025-03-01 20:54:24,294 - DEBUG - _bolt5.py:484 - [#C733]  S: SUCCESS {'t_first': 4, 'fields': ['i'], 'qid': 0}
2025-03-01 20:54:24,299 - DEBUG - _bolt5.py:484 - [#C733]  S: SUCCESS {'statuses': [{'gql_status': '02000', 'status_description': 'note: no data'}], 'type': 'r', 't_last': 3, 'db': 'neo4j'}
2025-03-01 20:54:24,300 - DEBUG - _bolt5.py:409 - [#C733]  C: COMMIT
2025-03-01 20:54:24,302 - DEBUG - _bolt5.py:100 - [#C733]  _: <CONNECTION> client state: TX_READY_OR_TX_STREAMING > READY
2025-03-01 20:54:24,305 - DEBUG - _bolt5.py:484 - [#C733]  S: SUCCESS {'bookmark': 'FB:kcwQOrtZU/fhTzKzbDGEPMs6mMk2V5A='}
2025-03-01 20:54:24,306 - DEBUG - _bolt5.py:89 - [#C733]  _: <CONNECTION> server state: TX_READY_OR_TX_STREAMING > READY
2025-03-01 20:54:24,307 - DEBUG - _pool.py:501 - [#C733]  _: <POOL> released bolt-9
2025-03-01 20:54:24,307 - INFO - api_routes.py:28 - No center node found for path: allianz_stadium_sydney01.jpg, trying alternatives
2025-03-01 20:54:24,309 - DEBUG - workspace.py:230 - [#0000]  _: <WORKSPACE> routing towards fixed database: None
2025-03-01 20:54:24,309 - DEBUG - workspace.py:122 - [#0000]  _: <WORKSPACE> pinning database: None
2025-03-01 20:54:24,310 - DEBUG - _pool.py:655 - [#0000]  _: <POOL> acquire direct connection, access_mode='READ', database=AcquisitionDatabase(name=None, guessed=False)
2025-03-01 20:54:24,311 - DEBUG - _pool.py:355 - [#C733]  _: <POOL> picked existing connection bolt-9
2025-03-01 20:54:24,311 - DEBUG - _pool.py:289 - [#C733]  _: <POOL> checked re_auth auth=None updated=False force=False
2025-03-01 20:54:24,312 - DEBUG - _pool.py:379 - [#C733]  _: <POOL> handing out existing connection
2025-03-01 20:54:24,312 - DEBUG - _bolt5.py:1039 - [#C733]  C: BEGIN {'mode': 'r'}
2025-03-01 20:54:24,313 - DEBUG - _bolt5.py:100 - [#C733]  _: <CONNECTION> client state: READY > TX_READY_OR_TX_STREAMING
2025-03-01 20:54:24,321 - DEBUG - _bolt5.py:484 - [#C733]  S: SUCCESS {}
2025-03-01 20:54:24,322 - DEBUG - _bolt5.py:89 - [#C733]  _: <CONNECTION> server state: READY > TX_READY_OR_TX_STREAMING
2025-03-01 20:54:24,322 - DEBUG - _bolt5.py:979 - [#C733]  C: RUN 'MATCH (i:Image {path: $image_path}) RETURN i' {'image_path': 'images/allianz_stadium_sydney01.jpg'} {}
2025-03-01 20:54:24,323 - DEBUG - _bolt5.py:342 - [#C733]  C: PULL {'n': 1000}
2025-03-01 20:54:24,331 - DEBUG - _bolt5.py:484 - [#C733]  S: SUCCESS {'t_first': 4, 'fields': ['i'], 'qid': 0}
2025-03-01 20:54:24,335 - DEBUG - _bolt5.py:484 - [#C733]  S: SUCCESS {'statuses': [{'gql_status': '02000', 'status_description': 'note: no data'}], 'type': 'r', 't_last': 2, 'db': 'neo4j'}
2025-03-01 20:54:24,336 - DEBUG - _bolt5.py:409 - [#C733]  C: COMMIT
2025-03-01 20:54:24,337 - DEBUG - _bolt5.py:100 - [#C733]  _: <CONNECTION> client state: TX_READY_OR_TX_STREAMING > READY
2025-03-01 20:54:24,340 - DEBUG - _bolt5.py:484 - [#C733]  S: SUCCESS {'bookmark': 'FB:kcwQOrtZU/fhTzKzbDGEPMs6mMk2V5A='}
2025-03-01 20:54:24,341 - DEBUG - _bolt5.py:89 - [#C733]  _: <CONNECTION> server state: TX_READY_OR_TX_STREAMING > READY
2025-03-01 20:54:24,342 - DEBUG - _pool.py:501 - [#C733]  _: <POOL> released bolt-9
2025-03-01 20:54:24,342 - DEBUG - workspace.py:230 - [#0000]  _: <WORKSPACE> routing towards fixed database: None
2025-03-01 20:54:24,343 - DEBUG - workspace.py:122 - [#0000]  _: <WORKSPACE> pinning database: None
2025-03-01 20:54:24,343 - DEBUG - _pool.py:655 - [#0000]  _: <POOL> acquire direct connection, access_mode='READ', database=AcquisitionDatabase(name=None, guessed=False)
2025-03-01 20:54:24,344 - DEBUG - _pool.py:355 - [#C733]  _: <POOL> picked existing connection bolt-9
2025-03-01 20:54:24,345 - DEBUG - _pool.py:289 - [#C733]  _: <POOL> checked re_auth auth=None updated=False force=False
2025-03-01 20:54:24,345 - DEBUG - _pool.py:379 - [#C733]  _: <POOL> handing out existing connection
2025-03-01 20:54:24,346 - DEBUG - _bolt5.py:1039 - [#C733]  C: BEGIN {'mode': 'r'}
2025-03-01 20:54:24,346 - DEBUG - _bolt5.py:100 - [#C733]  _: <CONNECTION> client state: READY > TX_READY_OR_TX_STREAMING
2025-03-01 20:54:24,354 - DEBUG - _bolt5.py:484 - [#C733]  S: SUCCESS {}
2025-03-01 20:54:24,355 - DEBUG - _bolt5.py:89 - [#C733]  _: <CONNECTION> server state: READY > TX_READY_OR_TX_STREAMING
2025-03-01 20:54:24,356 - DEBUG - _bolt5.py:979 - [#C733]  C: RUN 'MATCH (i:Image {path: $image_path}) RETURN i' {'image_path': 'allianz_stadium_sydney01.jpg'} {}
2025-03-01 20:54:24,357 - DEBUG - _bolt5.py:342 - [#C733]  C: PULL {'n': 1000}
2025-03-01 20:54:24,363 - DEBUG - _bolt5.py:484 - [#C733]  S: SUCCESS {'t_first': 3, 'fields': ['i'], 'qid': 0}
2025-03-01 20:54:24,366 - DEBUG - _bolt5.py:484 - [#C733]  S: SUCCESS {'statuses': [{'gql_status': '02000', 'status_description': 'note: no data'}], 'type': 'r', 't_last': 3, 'db': 'neo4j'}
2025-03-01 20:54:24,368 - DEBUG - _bolt5.py:409 - [#C733]  C: COMMIT
2025-03-01 20:54:24,369 - DEBUG - _bolt5.py:100 - [#C733]  _: <CONNECTION> client state: TX_READY_OR_TX_STREAMING > READY
2025-03-01 20:54:24,373 - DEBUG - _bolt5.py:484 - [#C733]  S: SUCCESS {'bookmark': 'FB:kcwQOrtZU/fhTzKzbDGEPMs6mMk2V5A='}
2025-03-01 20:54:24,373 - DEBUG - _bolt5.py:89 - [#C733]  _: <CONNECTION> server state: TX_READY_OR_TX_STREAMING > READY
2025-03-01 20:54:24,374 - DEBUG - _pool.py:501 - [#C733]  _: <POOL> released bolt-9
2025-03-01 20:54:24,375 - INFO - api_routes.py:52 - Returning data with 0 nodes and 0 edges
2025-03-01 20:54:24,376 - INFO - _internal.py:97 - 127.0.0.1 - - [01/Mar/2025 20:54:24] "GET /neighbors?image_path=allianz_stadium_sydney01.jpg&threshold=0.63&limit=20 HTTP/1.1" 200 -
2025-03-01 20:54:24,391 - ERROR - app.py:48 - Traceback (most recent call last):
  File "C:\Users\alexa\dev\AiR-Helix-View\venv\lib\site-packages\flask\app.py", line 917, in full_dispatch_request
    rv = self.dispatch_request()
  File "C:\Users\alexa\dev\AiR-Helix-View\venv\lib\site-packages\flask\app.py", line 902, in dispatch_request
    return self.ensure_sync(self.view_functions[rule.endpoint])(**view_args)  # type: ignore[no-any-return]
  File "C:\Users\alexa\dev\AiR-Helix-View\venv\lib\site-packages\flask\app.py", line 278, in <lambda>
    view_func=lambda **kw: self_ref().send_static_file(**kw),  # type: ignore # noqa: B950
  File "C:\Users\alexa\dev\AiR-Helix-View\venv\lib\site-packages\flask\app.py", line 326, in send_static_file
    return send_from_directory(
  File "C:\Users\alexa\dev\AiR-Helix-View\venv\lib\site-packages\flask\helpers.py", line 565, in send_from_directory
    return werkzeug.utils.send_from_directory(  # type: ignore[return-value]
  File "C:\Users\alexa\dev\AiR-Helix-View\venv\lib\site-packages\werkzeug\utils.py", line 575, in send_from_directory
    raise NotFound()
werkzeug.exceptions.NotFound: 404 Not Found: The requested URL was not found on the server. If you entered the URL manually please check your spelling and try again.

2025-03-01 20:54:24,393 - ERROR - app.py:48 - Traceback (most recent call last):
  File "C:\Users\alexa\dev\AiR-Helix-View\venv\lib\site-packages\flask\app.py", line 917, in full_dispatch_request
    rv = self.dispatch_request()
  File "C:\Users\alexa\dev\AiR-Helix-View\venv\lib\site-packages\flask\app.py", line 902, in dispatch_request
    return self.ensure_sync(self.view_functions[rule.endpoint])(**view_args)  # type: ignore[no-any-return]
  File "C:\Users\alexa\dev\AiR-Helix-View\venv\lib\site-packages\flask\app.py", line 278, in <lambda>
    view_func=lambda **kw: self_ref().send_static_file(**kw),  # type: ignore # noqa: B950
  File "C:\Users\alexa\dev\AiR-Helix-View\venv\lib\site-packages\flask\app.py", line 326, in send_static_file
    return send_from_directory(
  File "C:\Users\alexa\dev\AiR-Helix-View\venv\lib\site-packages\flask\helpers.py", line 565, in send_from_directory
    return werkzeug.utils.send_from_directory(  # type: ignore[return-value]
  File "C:\Users\alexa\dev\AiR-Helix-View\venv\lib\site-packages\werkzeug\utils.py", line 575, in send_from_directory
    raise NotFound()
werkzeug.exceptions.NotFound: 404 Not Found: The requested URL was not found on the server. If you entered the URL manually please check your spelling and try again.

2025-03-01 20:54:24,396 - INFO - _internal.py:97 - 127.0.0.1 - - [01/Mar/2025 20:54:24] "[35m[1mGET /static/allianz_stadium_sydney01.jpg?v=1740826464255 HTTP/1.1[0m" 500 -
2025-03-01 20:54:24,398 - INFO - _internal.py:97 - 127.0.0.1 - - [01/Mar/2025 20:54:24] "[35m[1mGET /static/allianz_stadium_sydney01.jpg?v=1740826464266 HTTP/1.1[0m" 500 -
2025-03-01 20:54:24,400 - ERROR - app.py:47 - Unhandled exception: 404 Not Found: The requested URL was not found on the server. If you entered the URL manually please check your spelling and try again.
2025-03-01 20:54:24,403 - ERROR - app.py:48 - Traceback (most recent call last):
  File "C:\Users\alexa\dev\AiR-Helix-View\venv\lib\site-packages\flask\app.py", line 917, in full_dispatch_request
    rv = self.dispatch_request()
  File "C:\Users\alexa\dev\AiR-Helix-View\venv\lib\site-packages\flask\app.py", line 902, in dispatch_request
    return self.ensure_sync(self.view_functions[rule.endpoint])(**view_args)  # type: ignore[no-any-return]
  File "C:\Users\alexa\dev\AiR-Helix-View\venv\lib\site-packages\flask\app.py", line 278, in <lambda>
    view_func=lambda **kw: self_ref().send_static_file(**kw),  # type: ignore # noqa: B950
  File "C:\Users\alexa\dev\AiR-Helix-View\venv\lib\site-packages\flask\app.py", line 326, in send_static_file
    return send_from_directory(
  File "C:\Users\alexa\dev\AiR-Helix-View\venv\lib\site-packages\flask\helpers.py", line 565, in send_from_directory
    return werkzeug.utils.send_from_directory(  # type: ignore[return-value]
  File "C:\Users\alexa\dev\AiR-Helix-View\venv\lib\site-packages\werkzeug\utils.py", line 575, in send_from_directory
    raise NotFound()
werkzeug.exceptions.NotFound: 404 Not Found: The requested URL was not found on the server. If you entered the URL manually please check your spelling and try again.

2025-03-01 20:54:24,407 - INFO - _internal.py:97 - 127.0.0.1 - - [01/Mar/2025 20:54:24] "[35m[1mGET /static/allianz_stadium_sydney01.jpg?v=1740826464391 HTTP/1.1[0m" 500 -
2025-03-01 20:54:24,409 - ERROR - app.py:47 - Unhandled exception: 404 Not Found: The requested URL was not found on the server. If you entered the URL manually please check your spelling and try again.
2025-03-01 20:54:24,411 - ERROR - app.py:48 - Traceback (most recent call last):
  File "C:\Users\alexa\dev\AiR-Helix-View\venv\lib\site-packages\flask\app.py", line 917, in full_dispatch_request
    rv = self.dispatch_request()
  File "C:\Users\alexa\dev\AiR-Helix-View\venv\lib\site-packages\flask\app.py", line 902, in dispatch_request
    return self.ensure_sync(self.view_functions[rule.endpoint])(**view_args)  # type: ignore[no-any-return]
  File "C:\Users\alexa\dev\AiR-Helix-View\venv\lib\site-packages\flask\app.py", line 278, in <lambda>
    view_func=lambda **kw: self_ref().send_static_file(**kw),  # type: ignore # noqa: B950
  File "C:\Users\alexa\dev\AiR-Helix-View\venv\lib\site-packages\flask\app.py", line 326, in send_static_file
    return send_from_directory(
  File "C:\Users\alexa\dev\AiR-Helix-View\venv\lib\site-packages\flask\helpers.py", line 565, in send_from_directory
    return werkzeug.utils.send_from_directory(  # type: ignore[return-value]
  File "C:\Users\alexa\dev\AiR-Helix-View\venv\lib\site-packages\werkzeug\utils.py", line 575, in send_from_directory
    raise NotFound()
werkzeug.exceptions.NotFound: 404 Not Found: The requested URL was not found on the server. If you entered the URL manually please check your spelling and try again.

2025-03-01 20:54:24,413 - INFO - _internal.py:97 - 127.0.0.1 - - [01/Mar/2025 20:54:24] "[35m[1mGET /static/allianz_stadium_sydney01.jpg?v=1740826464400 HTTP/1.1[0m" 500 -
2025-03-01 20:57:37,261 - INFO - _internal.py:97 -  * Detected change in 'C:\\Users\\alexa\\dev\\AiR-Helix-View\\backend\\graph.py', reloading
2025-03-01 20:57:38,387 - INFO - _internal.py:97 -  * Restarting with stat
2025-03-01 20:57:39,092 - INFO - image_utils.py:94 - Generated placeholder image at placeholder.png
2025-03-01 20:57:39,095 - INFO - app.py:69 - Available images in C:\Users\alexa\dev\AiR-Helix-View\frontend\public\images:
2025-03-01 20:57:39,098 - INFO - app.py:74 -  - allianz_stadium_sydney01.jpg
2025-03-01 20:57:39,098 - INFO - app.py:74 -  - allianz_stadium_sydney03.jpg
2025-03-01 20:57:39,098 - INFO - app.py:74 -  - allianz_stadium_sydney05.jpg
2025-03-01 20:57:39,099 - INFO - app.py:74 -  - allianz_stadium_sydney10.jpg
2025-03-01 20:57:39,099 - INFO - app.py:74 -  - campbelltown_stadium04.jpg
2025-03-01 20:57:39,099 - INFO - app.py:74 -  - canberra_stadium01.jpg
2025-03-01 20:57:39,099 - INFO - app.py:74 -  - canberra_stadium02.jpg
2025-03-01 20:57:39,100 - INFO - app.py:74 -  - canberra_stadium03.jpg
2025-03-01 20:57:39,100 - INFO - app.py:74 -  - canberra_stadium04.jpg
2025-03-01 20:57:39,101 - INFO - app.py:74 -  - central_coast_stadium01.jpg
2025-03-01 20:57:39,106 - INFO - app.py:77 -  ... and 113 more images
2025-03-01 20:57:39,106 - INFO - app.py:78 - Total images found: 123
2025-03-01 20:57:45,635 - INFO - graph.py:20 - Attempting to connect to Neo4j at bolt://localhost:7687
2025-03-01 20:57:45,635 - INFO - graph.py:21 - Username: neo4j
2025-03-01 20:57:45,636 - DEBUG - _pool.py:633 - [#0000]  _: <POOL> created, direct address IPv4Address(('localhost', 7687))
2025-03-01 20:57:45,637 - DEBUG - workspace.py:230 - [#0000]  _: <WORKSPACE> routing towards fixed database: None
2025-03-01 20:57:45,637 - DEBUG - workspace.py:122 - [#0000]  _: <WORKSPACE> pinning database: None
2025-03-01 20:57:45,637 - DEBUG - _pool.py:655 - [#0000]  _: <POOL> acquire direct connection, access_mode='READ', database=AcquisitionDatabase(name=None, guessed=False)
2025-03-01 20:57:45,638 - DEBUG - _pool.py:407 - [#0000]  _: <POOL> trying to hand out new connection
2025-03-01 20:57:45,638 - DEBUG - _util.py:178 - [#0000]  _: <RESOLVE> in: localhost:7687
2025-03-01 20:57:45,643 - DEBUG - _util.py:199 - [#0000]  _: <RESOLVE> dns resolver out: [::1]:7687
2025-03-01 20:57:45,643 - DEBUG - _bolt_socket.py:408 - [#0000]  C: <OPEN> [::1]:7687
2025-03-01 20:57:47,682 - DEBUG - _bolt_socket.py:420 - [#0000]  S: <ERROR> ConnectionRefusedError 10061 'No connection could be made because the target machine actively refused it' None 10061 None
2025-03-01 20:57:47,683 - DEBUG - _bolt_socket.py:457 - [#0000]  C: <CLOSE> [::1]:7687
2025-03-01 20:57:47,684 - DEBUG - _bolt_socket.py:343 - [#0000]  S: <CONNECTION FAILED> [::1]:7687 ServiceUnavailable: Failed to establish connection to ResolvedIPv6Address(('::1', 7687, 0, 0)) (reason [WinError 10061] No connection could be made because the target machine actively refused it)
2025-03-01 20:57:47,684 - DEBUG - _util.py:199 - [#0000]  _: <RESOLVE> dns resolver out: 127.0.0.1:7687
2025-03-01 20:57:47,684 - DEBUG - _bolt_socket.py:408 - [#0000]  C: <OPEN> 127.0.0.1:7687
2025-03-01 20:57:47,697 - DEBUG - _bolt_socket.py:239 - [#C85E]  C: <MAGIC> 0x6060B017
2025-03-01 20:57:47,697 - DEBUG - _bolt_socket.py:244 - [#C85E]  C: <HANDSHAKE> 0x000001FF 0x00080805 0x00020404 0x00000003
2025-03-01 20:57:47,700 - DEBUG - _bolt_socket.py:80 - [#C85E]  S: <HANDSHAKE> 0x00000605
2025-03-01 20:57:47,701 - DEBUG - _bolt5.py:728 - [#C85E]  C: HELLO {'user_agent': 'neo4j-python/5.28.1 Python/3.10.11-final-0 (win32)', 'bolt_agent': {'product': 'neo4j-python/5.28.1', 'platform': 'Windows 10; AMD64', 'language': 'Python/3.10.11-final-0', 'language_details': 'CPython; 3.10.11-final-0 (tags/v3.10.11:7d4cc5a, Apr  5 2023 00:38:17) [MSC v.1929 64 bit (AMD64)]'}}
2025-03-01 20:57:47,703 - DEBUG - _bolt5.py:100 - [#C85E]  _: <CONNECTION> client state: CONNECTED > AUTHENTICATION
2025-03-01 20:57:47,703 - DEBUG - _bolt5.py:666 - [#C85E]  C: LOGON {'scheme': 'basic', 'principal': 'neo4j', 'credentials': '*******'}
2025-03-01 20:57:47,704 - DEBUG - _bolt5.py:100 - [#C85E]  _: <CONNECTION> client state: AUTHENTICATION > READY
2025-03-01 20:57:47,707 - DEBUG - _bolt5.py:484 - [#C85E]  S: SUCCESS {'server': 'Neo4j/5.24.0', 'connection_id': 'bolt-10', 'hints': {'connection.recv_timeout_seconds': 120}}
2025-03-01 20:57:47,708 - DEBUG - _bolt5.py:89 - [#C85E]  _: <CONNECTION> server state: CONNECTED > AUTHENTICATION
2025-03-01 20:57:47,710 - DEBUG - _bolt5.py:484 - [#C85E]  S: SUCCESS {}
2025-03-01 20:57:47,711 - DEBUG - _bolt5.py:89 - [#C85E]  _: <CONNECTION> server state: AUTHENTICATION > READY
2025-03-01 20:57:47,712 - DEBUG - _pool.py:501 - [#C85E]  _: <POOL> released bolt-10
2025-03-01 20:57:47,713 - INFO - graph.py:28 - Successfully connected to Neo4j!
2025-03-01 20:57:47,713 - INFO - database.py:16 - Connected to Neo4j database
2025-03-01 20:57:47,713 - INFO - app.py:86 - Database connection verified
2025-03-01 20:57:47,725 - INFO - app.py:93 - Starting Flask application...
2025-03-01 20:57:47,734 - WARNING - _internal.py:97 -  * Debugger is active!
2025-03-01 20:57:47,745 - INFO - _internal.py:97 -  * Debugger PIN: 128-764-036
2025-03-01 20:57:50,001 - ERROR - app.py:47 - Unhandled exception: 404 Not Found: The requested URL was not found on the server. If you entered the URL manually please check your spelling and try again.
2025-03-01 20:57:50,004 - ERROR - app.py:47 - Unhandled exception: 'Neo4jConnection' object has no attribute 'get_neighbors'
2025-03-01 20:57:50,008 - ERROR - app.py:48 - Traceback (most recent call last):
  File "C:\Users\alexa\dev\AiR-Helix-View\venv\lib\site-packages\flask\app.py", line 917, in full_dispatch_request
    rv = self.dispatch_request()
  File "C:\Users\alexa\dev\AiR-Helix-View\venv\lib\site-packages\flask\app.py", line 902, in dispatch_request
    return self.ensure_sync(self.view_functions[rule.endpoint])(**view_args)  # type: ignore[no-any-return]
  File "C:\Users\alexa\dev\AiR-Helix-View\backend\routes\api_routes.py", line 24, in get_neighbors
    graph_data = db.get_neighbors(image_path, similarity_threshold, limit)
AttributeError: 'Neo4jConnection' object has no attribute 'get_neighbors'

2025-03-01 20:57:50,011 - ERROR - app.py:47 - Unhandled exception: 404 Not Found: The requested URL was not found on the server. If you entered the URL manually please check your spelling and try again.
2025-03-01 20:57:50,011 - ERROR - app.py:48 - Traceback (most recent call last):
  File "C:\Users\alexa\dev\AiR-Helix-View\venv\lib\site-packages\flask\app.py", line 917, in full_dispatch_request
    rv = self.dispatch_request()
  File "C:\Users\alexa\dev\AiR-Helix-View\venv\lib\site-packages\flask\app.py", line 902, in dispatch_request
    return self.ensure_sync(self.view_functions[rule.endpoint])(**view_args)  # type: ignore[no-any-return]
  File "C:\Users\alexa\dev\AiR-Helix-View\venv\lib\site-packages\flask\app.py", line 278, in <lambda>
    view_func=lambda **kw: self_ref().send_static_file(**kw),  # type: ignore # noqa: B950
  File "C:\Users\alexa\dev\AiR-Helix-View\venv\lib\site-packages\flask\app.py", line 326, in send_static_file
    return send_from_directory(
  File "C:\Users\alexa\dev\AiR-Helix-View\venv\lib\site-packages\flask\helpers.py", line 565, in send_from_directory
    return werkzeug.utils.send_from_directory(  # type: ignore[return-value]
  File "C:\Users\alexa\dev\AiR-Helix-View\venv\lib\site-packages\werkzeug\utils.py", line 575, in send_from_directory
    raise NotFound()
werkzeug.exceptions.NotFound: 404 Not Found: The requested URL was not found on the server. If you entered the URL manually please check your spelling and try again.

2025-03-01 20:57:50,012 - INFO - _internal.py:97 - 127.0.0.1 - - [01/Mar/2025 20:57:50] "[35m[1mGET /neighbors?image_path=allianz_stadium_sydney01.jpg&threshold=0.63&limit=20 HTTP/1.1[0m" 500 -
2025-03-01 20:57:50,013 - ERROR - app.py:48 - Traceback (most recent call last):
  File "C:\Users\alexa\dev\AiR-Helix-View\venv\lib\site-packages\flask\app.py", line 917, in full_dispatch_request
    rv = self.dispatch_request()
  File "C:\Users\alexa\dev\AiR-Helix-View\venv\lib\site-packages\flask\app.py", line 902, in dispatch_request
    return self.ensure_sync(self.view_functions[rule.endpoint])(**view_args)  # type: ignore[no-any-return]
  File "C:\Users\alexa\dev\AiR-Helix-View\venv\lib\site-packages\flask\app.py", line 278, in <lambda>
    view_func=lambda **kw: self_ref().send_static_file(**kw),  # type: ignore # noqa: B950
  File "C:\Users\alexa\dev\AiR-Helix-View\venv\lib\site-packages\flask\app.py", line 326, in send_static_file
    return send_from_directory(
  File "C:\Users\alexa\dev\AiR-Helix-View\venv\lib\site-packages\flask\helpers.py", line 565, in send_from_directory
    return werkzeug.utils.send_from_directory(  # type: ignore[return-value]
  File "C:\Users\alexa\dev\AiR-Helix-View\venv\lib\site-packages\werkzeug\utils.py", line 575, in send_from_directory
    raise NotFound()
werkzeug.exceptions.NotFound: 404 Not Found: The requested URL was not found on the server. If you entered the URL manually please check your spelling and try again.

2025-03-01 20:57:50,015 - INFO - _internal.py:97 - 127.0.0.1 - - [01/Mar/2025 20:57:50] "[35m[1mGET /static/allianz_stadium_sydney01.jpg?v=1740826669994 HTTP/1.1[0m" 500 -
2025-03-01 20:57:50,021 - INFO - _internal.py:97 - 127.0.0.1 - - [01/Mar/2025 20:57:50] "[35m[1mGET /static/allianz_stadium_sydney01.jpg?v=1740826670002 HTTP/1.1[0m" 500 -
2025-03-01 20:57:50,032 - ERROR - app.py:47 - Unhandled exception: 404 Not Found: The requested URL was not found on the server. If you entered the URL manually please check your spelling and try again.
2025-03-01 20:57:50,035 - ERROR - app.py:48 - Traceback (most recent call last):
  File "C:\Users\alexa\dev\AiR-Helix-View\venv\lib\site-packages\flask\app.py", line 917, in full_dispatch_request
    rv = self.dispatch_request()
  File "C:\Users\alexa\dev\AiR-Helix-View\venv\lib\site-packages\flask\app.py", line 902, in dispatch_request
    return self.ensure_sync(self.view_functions[rule.endpoint])(**view_args)  # type: ignore[no-any-return]
  File "C:\Users\alexa\dev\AiR-Helix-View\venv\lib\site-packages\flask\app.py", line 278, in <lambda>
    view_func=lambda **kw: self_ref().send_static_file(**kw),  # type: ignore # noqa: B950
  File "C:\Users\alexa\dev\AiR-Helix-View\venv\lib\site-packages\flask\app.py", line 326, in send_static_file
    return send_from_directory(
  File "C:\Users\alexa\dev\AiR-Helix-View\venv\lib\site-packages\flask\helpers.py", line 565, in send_from_directory
    return werkzeug.utils.send_from_directory(  # type: ignore[return-value]
  File "C:\Users\alexa\dev\AiR-Helix-View\venv\lib\site-packages\werkzeug\utils.py", line 575, in send_from_directory
    raise NotFound()
werkzeug.exceptions.NotFound: 404 Not Found: The requested URL was not found on the server. If you entered the URL manually please check your spelling and try again.

2025-03-01 20:57:50,039 - INFO - _internal.py:97 - 127.0.0.1 - - [01/Mar/2025 20:57:50] "[35m[1mGET /static/allianz_stadium_sydney01.jpg?v=1740826670025 HTTP/1.1[0m" 500 -
2025-03-01 20:57:50,950 - ERROR - app.py:47 - Unhandled exception: 404 Not Found: The requested URL was not found on the server. If you entered the URL manually please check your spelling and try again.
2025-03-01 20:57:50,952 - ERROR - app.py:48 - Traceback (most recent call last):
  File "C:\Users\alexa\dev\AiR-Helix-View\venv\lib\site-packages\flask\app.py", line 917, in full_dispatch_request
    rv = self.dispatch_request()
  File "C:\Users\alexa\dev\AiR-Helix-View\venv\lib\site-packages\flask\app.py", line 902, in dispatch_request
    return self.ensure_sync(self.view_functions[rule.endpoint])(**view_args)  # type: ignore[no-any-return]
  File "C:\Users\alexa\dev\AiR-Helix-View\venv\lib\site-packages\flask\app.py", line 278, in <lambda>
    view_func=lambda **kw: self_ref().send_static_file(**kw),  # type: ignore # noqa: B950
  File "C:\Users\alexa\dev\AiR-Helix-View\venv\lib\site-packages\flask\app.py", line 326, in send_static_file
    return send_from_directory(
  File "C:\Users\alexa\dev\AiR-Helix-View\venv\lib\site-packages\flask\helpers.py", line 565, in send_from_directory
    return werkzeug.utils.send_from_directory(  # type: ignore[return-value]
  File "C:\Users\alexa\dev\AiR-Helix-View\venv\lib\site-packages\werkzeug\utils.py", line 575, in send_from_directory
    raise NotFound()
werkzeug.exceptions.NotFound: 404 Not Found: The requested URL was not found on the server. If you entered the URL manually please check your spelling and try again.

2025-03-01 20:57:50,954 - ERROR - app.py:47 - Unhandled exception: 'Neo4jConnection' object has no attribute 'get_neighbors'
2025-03-01 20:57:50,955 - INFO - _internal.py:97 - 127.0.0.1 - - [01/Mar/2025 20:57:50] "[35m[1mGET /static/allianz_stadium_sydney01.jpg?v=1740826670944 HTTP/1.1[0m" 500 -
2025-03-01 20:57:50,956 - ERROR - app.py:48 - Traceback (most recent call last):
  File "C:\Users\alexa\dev\AiR-Helix-View\venv\lib\site-packages\flask\app.py", line 917, in full_dispatch_request
    rv = self.dispatch_request()
  File "C:\Users\alexa\dev\AiR-Helix-View\venv\lib\site-packages\flask\app.py", line 902, in dispatch_request
    return self.ensure_sync(self.view_functions[rule.endpoint])(**view_args)  # type: ignore[no-any-return]
  File "C:\Users\alexa\dev\AiR-Helix-View\backend\routes\api_routes.py", line 24, in get_neighbors
    graph_data = db.get_neighbors(image_path, similarity_threshold, limit)
AttributeError: 'Neo4jConnection' object has no attribute 'get_neighbors'

2025-03-01 20:57:50,957 - ERROR - app.py:47 - Unhandled exception: 404 Not Found: The requested URL was not found on the server. If you entered the URL manually please check your spelling and try again.
2025-03-01 20:57:50,959 - INFO - _internal.py:97 - 127.0.0.1 - - [01/Mar/2025 20:57:50] "[35m[1mGET /neighbors?image_path=allianz_stadium_sydney01.jpg&threshold=0.63&limit=20 HTTP/1.1[0m" 500 -
2025-03-01 20:57:50,960 - ERROR - app.py:48 - Traceback (most recent call last):
  File "C:\Users\alexa\dev\AiR-Helix-View\venv\lib\site-packages\flask\app.py", line 917, in full_dispatch_request
    rv = self.dispatch_request()
  File "C:\Users\alexa\dev\AiR-Helix-View\venv\lib\site-packages\flask\app.py", line 902, in dispatch_request
    return self.ensure_sync(self.view_functions[rule.endpoint])(**view_args)  # type: ignore[no-any-return]
  File "C:\Users\alexa\dev\AiR-Helix-View\venv\lib\site-packages\flask\app.py", line 278, in <lambda>
    view_func=lambda **kw: self_ref().send_static_file(**kw),  # type: ignore # noqa: B950
  File "C:\Users\alexa\dev\AiR-Helix-View\venv\lib\site-packages\flask\app.py", line 326, in send_static_file
    return send_from_directory(
  File "C:\Users\alexa\dev\AiR-Helix-View\venv\lib\site-packages\flask\helpers.py", line 565, in send_from_directory
    return werkzeug.utils.send_from_directory(  # type: ignore[return-value]
  File "C:\Users\alexa\dev\AiR-Helix-View\venv\lib\site-packages\werkzeug\utils.py", line 575, in send_from_directory
    raise NotFound()
werkzeug.exceptions.NotFound: 404 Not Found: The requested URL was not found on the server. If you entered the URL manually please check your spelling and try again.

2025-03-01 20:57:50,962 - INFO - _internal.py:97 - 127.0.0.1 - - [01/Mar/2025 20:57:50] "[35m[1mGET /static/allianz_stadium_sydney01.jpg?v=1740826670952 HTTP/1.1[0m" 500 -
2025-03-01 20:57:50,979 - ERROR - app.py:47 - Unhandled exception: 404 Not Found: The requested URL was not found on the server. If you entered the URL manually please check your spelling and try again.
2025-03-01 20:57:50,980 - ERROR - app.py:48 - Traceback (most recent call last):
  File "C:\Users\alexa\dev\AiR-Helix-View\venv\lib\site-packages\flask\app.py", line 917, in full_dispatch_request
    rv = self.dispatch_request()
  File "C:\Users\alexa\dev\AiR-Helix-View\venv\lib\site-packages\flask\app.py", line 902, in dispatch_request
    return self.ensure_sync(self.view_functions[rule.endpoint])(**view_args)  # type: ignore[no-any-return]
  File "C:\Users\alexa\dev\AiR-Helix-View\venv\lib\site-packages\flask\app.py", line 278, in <lambda>
    view_func=lambda **kw: self_ref().send_static_file(**kw),  # type: ignore # noqa: B950
  File "C:\Users\alexa\dev\AiR-Helix-View\venv\lib\site-packages\flask\app.py", line 326, in send_static_file
    return send_from_directory(
  File "C:\Users\alexa\dev\AiR-Helix-View\venv\lib\site-packages\flask\helpers.py", line 565, in send_from_directory
    return werkzeug.utils.send_from_directory(  # type: ignore[return-value]
  File "C:\Users\alexa\dev\AiR-Helix-View\venv\lib\site-packages\werkzeug\utils.py", line 575, in send_from_directory
    raise NotFound()
werkzeug.exceptions.NotFound: 404 Not Found: The requested URL was not found on the server. If you entered the URL manually please check your spelling and try again.

2025-03-01 20:57:50,982 - INFO - _internal.py:97 - 127.0.0.1 - - [01/Mar/2025 20:57:50] "[35m[1mGET /static/allianz_stadium_sydney01.jpg?v=1740826670976 HTTP/1.1[0m" 500 -
